Workbook

Sheet Instruções
B1: Base de Preços PROBUILT – preços reais
B2: v1.0 · Margem calculada SOBRE O CUSTO · Estrutura compatível com a folha _Produção_Folha_de_orçamento.xlsx
B4: COMO FUNCIONA O PREÇO
B5: 1. Custo direto | C5: Soma de Mão de obra + Materiais + Equipamento + Subempreitada (colunas E–H). Se o artigo ainda não estiver decomposto, usa o «Preço global» (coluna I).
B6: 2. Custo c/ encargos | C6: Cada parcela é agravada pela percentagem de encargos da folha Config (iguais à sua folha de orçamento: MO 1 %, Mat. 3 %, Equip. 2 %, Subemp. 2 %). O preço global usa o encargo médio.
B7: 3. Preço de venda | C7: PV = Custo c/ encargos × (1 + Margem). A margem é SOBRE O CUSTO. Por omissão usa a margem padrão da Config; pode definir uma margem própria por artigo (coluna L).
B8: Exemplo | C8: Custo c/ encargos 100,00 € e margem 20 % → PV = 120,00 €. (A base 2026 anterior fazia 100 / 0,75 = 133,33 €, ou seja, 33 % sobre o custo.)
B10: FIABILIDADE DO PREÇO (coluna R)
B11: A | C11: Preço real: fatura, contrato ou adjudicação.
B12: B | C12: Preço de orçamento próprio ou proposta de subempreiteiro/fornecedor.
B13: C | C13: Referência de mercado – usar com cautela e substituir logo que haja preço B ou A.
B15: CÉLULAS A PREENCHER / CORES
B16: Fundo amarelo | C16: Dados de entrada (decomposição, preço global, margem própria, fonte, obra, data, fiabilidade).
B17: Texto azul | C17: Valor introduzido manualmente (preço).
B18: Texto preto | C18: Fórmula – não editar.
B20: REGISTO DE PREÇOS (folha Registo)
B21: Para que serve | C21: Sempre que receber um preço novo (proposta, fatura, orçamento), registe-o com o código do artigo. A Base mostra automaticamente o n.º de registos e o último preço registado, para decidir quando atualizar o preço do artigo.
B22: Exemplo | C22: 15/10/2026 · ARQ.21 · Moradia X · Proposta pintor Y · 7,90 € · B
B24: NOTAS
C25: • Origem: 115 artigos da BASE_PRECOS_2026 (referência de mercado, fiabilidade C) + 32 artigos do orçamento da Ribeira (L99), preços de custo antes de margem (fiabilidade B).
C26: • Os preços da Ribeira incluem agravamento por acesso condicionado – ver observações; numa obra sem condicionantes podem ser mais baixos.
C27: • HID.05–HID.08 passaram para ESG e TER.04–TER.05 para ACU (códigos mantidos para rastreabilidade).
C28: • Especialidades alinhadas com as pastas do Drive: ARQ, EST, HID (inclui PLU), ESG, ELE, ITED, AVAC, GAS, SCIE, TERM, ACU, + GER e CARP para orçamento.

Sheet Base
A1: BASE DE PREÇOS PROBUILT
A2: ="Margem padrão sobre o custo: "&TEXT(Config!$C$3,"0%")&" · Artigos: "&COUNTA(A5:A1000)&" · Fiabilidade A/B/C: "&COUNTIF(R5:R1000,"A")&" / "&COUNTIF(R5:R1000,"B")&" / "&COUNTIF(R5:R1000,"C") -> Margem padrão sobre o custo: 20% · Artigos: 147 · Fiabilidade A/B/C: 0 / 32 / 115
A4: Cód. | B4: Designação | C4: Esp. | D4: Un. | E4: Mão de obra (€) | F4: Materiais (€) | G4: Equipamento (€) | H4: Subempreitada (€) | I4: Preço global s/ decomp. (€) | J4: Custo direto (€) | K4: Custo c/ encargos (€) | L4: Margem própria (s/ custo) | M4: Margem aplicada | N4: PV unitário (€) | O4: Fonte | P4: Obra de origem | Q4: Data | R4: Fiabilidade | S4: N.º registos | T4: Último preço registado (€) | U4: Observações
A5: GER.01 | B5: Estaleiro: proteções de pavimentos e superfícies, sinalização, condicionamento de acessos (obra pequena) | C5: GER | D5: vg | I5: 350 | J5: =IF(AND(A5="",B5=""),"",IF(SUM(E5:H5)>0,SUM(E5:H5),I5)) -> 350 | K5: =IF(J5="","",ROUND(IF(SUM(E5:H5)>0,E5*(1+Config!$C$4)+F5*(1+Config!$C$5)+G5*(1+Config!$C$6)+H5*(1+Config!$C$7),I5*(1+Config!$C$8)),2)) -> 357 | M5: =IF(J5="","",IF(L5="",Config!$C$3,L5)) -> 0.2 | N5: =IF(K5="","",ROUND(K5*(1+M5),2)) -> 428.4 | O5: Orçamento próprio (custo, antes de margem) | P5: Ribeira – remodelação (L99) | Q5: 2026 | R5: B | S5: =IF(A5="","",COUNTIF(Registo!$B$2:$B$501,A5)) -> 0 | T5: =IF(OR(A5="",S5=0),"",LOOKUP(2,1/(Registo!$B$2:$B$501=A5),Registo!$E$2:$E$501)) | U5: Inclui agravamento por acesso condicionado (transporte manual 100 m + escadaria, 1.º andar s/ elevador)
A6: GER.02 | B6: Limpeza final de obra e entrega em condições de habitabilidade (obra pequena) | C6: GER | D6: vg | I6: 500 | J6: =IF(AND(A6="",B6=""),"",IF(SUM(E6:H6)>0,SUM(E6:H6),I6)) -> 500 | K6: =IF(J6="","",ROUND(IF(SUM(E6:H6)>0,E6*(1+Config!$C$4)+F6*(1+Config!$C$5)+G6*(1+Config!$C$6)+H6*(1+Config!$C$7),I6*(1+Config!$C$8)),2)) -> 510 | M6: =IF(J6="","",IF(L6="",Config!$C$3,L6)) -> 0.2 | N6: =IF(K6="","",ROUND(K6*(1+M6),2)) -> 612 | O6: Orçamento próprio (custo, antes de margem) | P6: Ribeira – remodelação (L99) | Q6: 2026 | R6: B | S6: =IF(A6="","",COUNTIF(Registo!$B$2:$B$501,A6)) -> 0 | T6: =IF(OR(A6="",S6=0),"",LOOKUP(2,1/(Registo!$B$2:$B$501=A6),Registo!$E$2:$E$501)) | U6: Inclui agravamento por acesso condicionado (transporte manual 100 m + escadaria, 1.º andar s/ elevador)
A7: ARQ.01 | B7: Demolição de paredes em tijolo | C7: ARQ | D7: m² | I7: 12 | J7: =IF(AND(A7="",B7=""),"",IF(SUM(E7:H7)>0,SUM(E7:H7),I7)) -> 12 | K7: =IF(J7="","",ROUND(IF(SUM(E7:H7)>0,E7*(1+Config!$C$4)+F7*(1+Config!$C$5)+G7*(1+Config!$C$6)+H7*(1+Config!$C$7),I7*(1+Config!$C$8)),2)) -> 12.24 | M7: =IF(J7="","",IF(L7="",Config!$C$3,L7)) -> 0.2 | N7: =IF(K7="","",ROUND(K7*(1+M7),2)) -> 14.69 | O7: Referência de mercado Porto/Aveiro (BASE_PRECOS_2026) | Q7: Jun-2026 | R7: C | S7: =IF(A7="","",COUNTIF(Registo!$B$2:$B$501,A7)) -> 0 | T7: =IF(OR(A7="",S7=0),"",LOOKUP(2,1/(Registo!$B$2:$B$501=A7),Registo!$E$2:$E$501))
A8: ARQ.02 | B8: Demolição de pavimento em betão | C8: ARQ | D8: m² | I8: 18 | J8: =IF(AND(A8="",B8=""),"",IF(SUM(E8:H8)>0,SUM(E8:H8),I8)) -> 18 | K8: =IF(J8="","",ROUND(IF(SUM(E8:H8)>0,E8*(1+Config!$C$4)+F8*(1+Config!$C$5)+G8*(1+Config!$C$6)+H8*(1+Config!$C$7),I8*(1+Config!$C$8)),2)) -> 18.36 | M8: =IF(J8="","",IF(L8="",Config!$C$3,L8)) -> 0.2 | N8: =IF(K8="","",ROUND(K8*(1+M8),2)) -> 22.03 | O8: Referência de mercado Porto/Aveiro (BASE_PRECOS_2026) | Q8: Jun-2026 | R8: C | S8: =IF(A8="","",COUNTIF(Registo!$B$2:$B$501,A8)) -> 0 | T8: =IF(OR(A8="",S8=0),"",LOOKUP(2,1/(Registo!$B$2:$B$501=A8),Registo!$E$2:$E$501))
A9: ARQ.03 | B9: Demolição de cobertura em telha | C9: ARQ | D9: m² | I9: 14 | J9: =IF(AND(A9="",B9=""),"",IF(SUM(E9:H9)>0,SUM(E9:H9),I9)) -> 14 | K9: =IF(J9="","",ROUND(IF(SUM(E9:H9)>0,E9*(1+Config!$C$4)+F9*(1+Config!$C$5)+G9*(1+Config!$C$6)+H9*(1+Config!$C$7),I9*(1+Config!$C$8)),2)) -> 14.28 | M9: =IF(J9="","",IF(L9="",Config!$C$3,L9)) -> 0.2 | N9: =IF(K9="","",ROUND(K9*(1+M9),2)) -> 17.14 | O9: Referência de mercado Porto/Aveiro (BASE_PRECOS_2026) | Q9: Jun-2026 | R9: C | S9: =IF(A9="","",COUNTIF(Registo!$B$2:$B$501,A9)) -> 0 | T9: =IF(OR(A9="",S9=0),"",LOOKUP(2,1/(Registo!$B$2:$B$501=A9),Registo!$E$2:$E$501))
A10: ARQ.04 | B10: Paredes exteriores pano duplo tijolo 11+11 c/ caixa ar | C10: ARQ | D10: m² | I10: 55 | J10: =IF(AND(A10="",B10=""),"",IF(SUM(E10:H10)>0,SUM(E10:H10),I10)) -> 55 | K10: =IF(J10="","",ROUND(IF(SUM(E10:H10)>0,E10*(1+Config!$C$4)+F10*(1+Config!$C$5)+G10*(1+Config!$C$6)+H10*(1+Config!$C$7),I10*(1+Config!$C$8)),2)) -> 56.1 | M10: =IF(J10="","",IF(L10="",Config!$C$3,L10)) -> 0.2 | N10: =IF(K10="","",ROUND(K10*(1+M10),2)) -> 67.32 | O10: Referência de mercado Porto/Aveiro (BASE_PRECOS_2026) | Q10: Jun-2026 | R10: C | S10: =IF(A10="","",COUNTIF(Registo!$B$2:$B$501,A10)) -> 0 | T10: =IF(OR(A10="",S10=0),"",LOOKUP(2,1/(Registo!$B$2:$B$501=A10),Registo!$E$2:$E$501))
A11: ARQ.05 | B11: Paredes interiores tijolo 11 | C11: ARQ | D11: m² | I11: 32 | J11: =IF(AND(A11="",B11=""),"",IF(SUM(E11:H11)>0,SUM(E11:H11),I11)) -> 32 | K11: =IF(J11="","",ROUND(IF(SUM(E11:H11)>0,E11*(1+Config!$C$4)+F11*(1+Config!$C$5)+G11*(1+Config!$C$6)+H11*(1+Config!$C$7),I11*(1+Config!$C$8)),2)) -> 32.64 | M11: =IF(J11="","",IF(L11="",Config!$C$3,L11)) -> 0.2 | N11: =IF(K11="","",ROUND(K11*(1+M11),2)) -> 39.17 | O11: Referência de mercado Porto/Aveiro (BASE_PRECOS_2026) | Q11: Jun-2026 | R11: C | S11: =IF(A11="","",COUNTIF(Registo!$B$2:$B$501,A11)) -> 0 | T11: =IF(OR(A11="",S11=0),"",LOOKUP(2,1/(Registo!$B$2:$B$501=A11),Registo!$E$2:$E$501))
A12: ARQ.06 | B12: Paredes interiores tijolo 7 | C12: ARQ | D12: m² | I12: 26 | J12: =IF(AND(A12="",B12=""),"",IF(SUM(E12:H12)>0,SUM(E12:H12),I12)) -> 26 | K12: =IF(J12="","",ROUND(IF(SUM(E12:H12)>0,E12*(1+Config!$C$4)+F12*(1+Config!$C$5)+G12*(1+Config!$C$6)+H12*(1+Config!$C$7),I12*(1+Config!$C$8)),2)) -> 26.52 | M12: =IF(J12="","",IF(L12="",Config!$C$3,L12)) -> 0.2 | N12: =IF(K12="","",ROUND(K12*(1+M12),2)) -> 31.82 | O12: Referência de mercado Porto/Aveiro (BASE_PRECOS_2026) | Q12: Jun-2026 | R12: C | S12: =IF(A12="","",COUNTIF(Registo!$B$2:$B$501,A12)) -> 0 | T12: =IF(OR(A12="",S12=0),"",LOOKUP(2,1/(Registo!$B$2:$B$501=A12),Registo!$E$2:$E$501))
A13: ARQ.07 | B13: Reboco interior argamassa tradicional | C13: ARQ | D13: m² | I13: 18 | J13: =IF(AND(A13="",B13=""),"",IF(SUM(E13:H13)>0,SUM(E13:H13),I13)) -> 18 | K13: =IF(J13="","",ROUND(IF(SUM(E13:H13)>0,E13*(1+Config!$C$4)+F13*(1+Config!$C$5)+G13*(1+Config!$C$6)+H13*(1+Config!$C$7),I13*(1+Config!$C$8)),2)) -> 18.36 | M13: =IF(J13="","",IF(L13="",Config!$C$3,L13)) -> 0.2 | N13: =IF(K13="","",ROUND(K13*(1+M13),2)) -> 22.03 | O13: Referência de mercado Porto/Aveiro (BASE_PRECOS_2026) | Q13: Jun-2026 | R13: C | S13: =IF(A13="","",COUNTIF(Registo!$B$2:$B$501,A13)) -> 0 | T13: =IF(OR(A13="",S13=0),"",LOOKUP(2,1/(Registo!$B$2:$B$501=A13),Registo!$E$2:$E$501))
A14: ARQ.08 | B14: Reboco exterior argamassa monocamada | C14: ARQ | D14: m² | I14: 22 | J14: =IF(AND(A14="",B14=""),"",IF(SUM(E14:H14)>0,SUM(E14:H14),I14)) -> 22 | K14: =IF(J14="","",ROUND(IF(SUM(E14:H14)>0,E14*(1+Config!$C$4)+F14*(1+Config!$C$5)+G14*(1+Config!$C$6)+H14*(1+Config!$C$7),I14*(1+Config!$C$8)),2)) -> 22.44 | M14: =IF(J14="","",IF(L14="",Config!$C$3,L14)) -> 0.2 | N14: =IF(K14="","",ROUND(K14*(1+M14),2)) -> 26.93 | O14: Referência de mercado Porto/Aveiro (BASE_PRECOS_2026) | Q14: Jun-2026 | R14: C | S14: =IF(A14="","",COUNTIF(Registo!$B$2:$B$501,A14)) -> 0 | T14: =IF(OR(A14="",S14=0),"",LOOKUP(2,1/(Registo!$B$2:$B$501=A14),Registo!$E$2:$E$501))
A15: ARQ.09 | B15: ETICS parede exterior (EPS 60mm + acabamento) | C15: ARQ | D15: m² | I15: 65 | J15: =IF(AND(A15="",B15=""),"",IF(SUM(E15:H15)>0,SUM(E15:H15),I15)) -> 65 | K15: =IF(J15="","",ROUND(IF(SUM(E15:H15)>0,E15*(1+Config!$C$4)+F15*(1+Config!$C$5)+G15*(1+Config!$C$6)+H15*(1+Config!$C$7),I15*(1+Config!$C$8)),2)) -> 66.3 | M15: =IF(J15="","",IF(L15="",Config!$C$3,L15)) -> 0.2 | N15: =IF(K15="","",ROUND(K15*(1+M15),2)) -> 79.56 | O15: Referência de mercado Porto/Aveiro (BASE_PRECOS_2026) | Q15: Jun-2026 | R15: C | S15: =IF(A15="","",COUNTIF(Registo!$B$2:$B$501,A15)) -> 0 | T15: =IF(OR(A15="",S15=0),"",LOOKUP(2,1/(Registo!$B$2:$B$501=A15),Registo!$E$2:$E$501))
A16: ARQ.10 | B16: ETICS parede exterior (EPS 80mm + acabamento) | C16: ARQ | D16: m² | I16: 72 | J16: =IF(AND(A16="",B16=""),"",IF(SUM(E16:H16)>0,SUM(E16:H16),I16)) -> 72 | K16: =IF(J16="","",ROUND(IF(SUM(E16:H16)>0,E16*(1+Config!$C$4)+F16*(1+Config!$C$5)+G16*(1+Config!$C$6)+H16*(1+Config!$C$7),I16*(1+Config!$C$8)),2)) -> 73.44 | M16: =IF(J16="","",IF(L16="",Config!$C$3,L16)) -> 0.2 | N16: =IF(K16="","",ROUND(K16*(1+M16),2)) -> 88.13 | O16: Referência de mercado Porto/Aveiro (BASE_PRECOS_2026) | Q16: Jun-2026 | R16: C | S16: =IF(A16="","",COUNTIF(Registo!$B$2:$B$501,A16)) -> 0 | T16: =IF(OR(A16="",S16=0),"",LOOKUP(2,1/(Registo!$B$2:$B$501=A16),Registo!$E$2:$E$501))
A17: ARQ.11 | B17: Revestimento cerâmico parede interior (colocação) | C17: ARQ | D17: m² | I17: 28 | J17: =IF(AND(A17="",B17=""),"",IF(SUM(E17:H17)>0,SUM(E17:H17),I17)) -> 28 | K17: =IF(J17="","",ROUND(IF(SUM(E17:H17)>0,E17*(1+Config!$C$4)+F17*(1+Config!$C$5)+G17*(1+Config!$C$6)+H17*(1+Config!$C$7),I17*(1+Config!$C$8)),2)) -> 28.56 | M17: =IF(J17="","",IF(L17="",Config!$C$3,L17)) -> 0.2 | N17: =IF(K17="","",ROUND(K17*(1+M17),2)) -> 34.27 | O17: Referência de mercado Porto/Aveiro (BASE_PRECOS_2026) | Q17: Jun-2026 | R17: C | S17: =IF(A17="","",COUNTIF(Registo!$B$2:$B$501,A17)) -> 0 | T17: =IF(OR(A17="",S17=0),"",LOOKUP(2,1/(Registo!$B$2:$B$501=A17),Registo!$E$2:$E$501))
A18: ARQ.12 | B18: Revestimento cerâmico parede exterior (colocação) | C18: ARQ | D18: m² | I18: 32 | J18: =IF(AND(A18="",B18=""),"",IF(SUM(E18:H18)>0,SUM(E18:H18),I18)) -> 32 | K18: =IF(J18="","",ROUND(IF(SUM(E18:H18)>0,E18*(1+Config!$C$4)+F18*(1+Config!$C$5)+G18*(1+Config!$C$6)+H18*(1+Config!$C$7),I18*(1+Config!$C$8)),2)) -> 32.64 | M18: =IF(J18="","",IF(L18="",Config!$C$3,L18)) -> 0.2 | N18: =IF(K18="","",ROUND(K18*(1+M18),2)) -> 39.17 | O18: Referência de mercado Porto/Aveiro (BASE_PRECOS_2026) | Q18: Jun-2026 | R18: C | S18: =IF(A18="","",COUNTIF(Registo!$B$2:$B$501,A18)) -> 0 | T18: =IF(OR(A18="",S18=0),"",LOOKUP(2,1/(Registo!$B$2:$B$501=A18),Registo!$E$2:$E$501))
... A36: ARQ.30 | B36: Guarda-corpo inox escovado | C36: ARQ | D36: m | I36: 320 | J36: =IF(AND(A36="",B36=""),"",IF(SUM(E36:H36)>0,SUM(E36:H36),I36)) -> 320 | K36: =IF(J36="","",ROUND(IF(SUM(E36:H36)>0,E36*(1+Config!$C$4)+F36*(1+Config!$C$5)+G36*(1+Config!$C$6)+H36*(1+Config!$C$7),I36*(1+Config!$C$8)),2)) -> 326.4 | M36: =IF(J36="","",IF(L36="",Config!$C$3,L36)) -> 0.2 | N36: =IF(K36="","",ROUND(K36*(1+M36),2)) -> 391.68 | O36: Referência de mercado Porto/Aveiro (BASE_PRECOS_2026) | Q36: Jun-2026 | R36: C | S36: =IF(A36="","",COUNTIF(Registo!$B$2:$B$501,A36)) -> 0 | T36: =IF(OR(A36="",S36=0),"",LOOKUP(2,1/(Registo!$B$2:$B$501=A36),Registo!$E$2:$E$501))
A37: ARQ.31 | B37: Demolição de parede interior em alvenaria existente, c/ ensacamento manual, transporte à mão e remoção a vazadouro | C37: ARQ | D37: m² | I37: 55 | J37: =IF(AND(A37="",B37=""),"",IF(SUM(E37:H37)>0,SUM(E37:H37),I37)) -> 55 | K37: =IF(J37="","",ROUND(IF(SUM(E37:H37)>0,E37*(1+Config!$C$4)+F37*(1+Config!$C$5)+G37*(1+Config!$C$6)+H37*(1+Config!$C$7),I37*(1+Config!$C$8)),2)) -> 56.1 | M37: =IF(J37="","",IF(L37="",Config!$C$3,L37)) -> 0.2 | N37: =IF(K37="","",ROUND(K37*(1+M37),2)) -> 67.32 | O37: Orçamento próprio (custo, antes de margem) | P37: Ribeira – remodelação (L99) | Q37: 2026 | R37: B | S37: =IF(A37="","",COUNTIF(Registo!$B$2:$B$501,A37)) -> 0 | T37: =IF(OR(A37="",S37=0),"",LOOKUP(2,1/(Registo!$B$2:$B$501=A37),Registo!$E$2:$E$501)) | U37: Inclui agravamento por acesso condicionado (transporte manual 100 m + escadaria, 1.º andar s/ elevador)
A38: ARQ.32 | B38: Abertura e fecho de vãos em alvenaria rebocada, incl. lintéis e regularização | C38: ARQ | D38: un | I38: 480 | J38: =IF(AND(A38="",B38=""),"",IF(SUM(E38:H38)>0,SUM(E38:H38),I38)) -> 480 | K38: =IF(J38="","",ROUND(IF(SUM(E38:H38)>0,E38*(1+Config!$C$4)+F38*(1+Config!$C$5)+G38*(1+Config!$C$6)+H38*(1+Config!$C$7),I38*(1+Config!$C$8)),2)) -> 489.6 | M38: =IF(J38="","",IF(L38="",Config!$C$3,L38)) -> 0.2 | N38: =IF(K38="","",ROUND(K38*(1+M38),2)) -> 587.52 | O38: Orçamento próprio (custo, antes de margem) | P38: Ribeira – remodelação (L99) | Q38: 2026 | R38: B | S38: =IF(A38="","",COUNTIF(Registo!$B$2:$B$501,A38)) -> 0 | T38: =IF(OR(A38="",S38=0),"",LOOKUP(2,1/(Registo!$B$2:$B$501=A38),Registo!$E$2:$E$501)) | U38: Inclui agravamento por acesso condicionado (transporte manual 100 m + escadaria, 1.º andar s/ elevador)
A39: ARQ.33 | B39: Parede em pladur standard BA13 c/ estrutura metálica galvanizada, juntas tratadas, pronta a pintar | C39: ARQ | D39: m² | I39: 58 | J39: =IF(AND(A39="",B39=""),"",IF(SUM(E39:H39)>0,SUM(E39:H39),I39)) -> 58 | K39: =IF(J39="","",ROUND(IF(SUM(E39:H39)>0,E39*(1+Config!$C$4)+F39*(1+Config!$C$5)+G39*(1+Config!$C$6)+H39*(1+Config!$C$7),I39*(1+Config!$C$8)),2)) -> 59.16 | M39: =IF(J39="","",IF(L39="",Config!$C$3,L39)) -> 0.2 | N39: =IF(K39="","",ROUND(K39*(1+M39),2)) -> 70.99 | O39: Orçamento próprio (custo, antes de margem) | P39: Ribeira – remodelação (L99) | Q39: 2026 | R39: B | S39: =IF(A39="","",COUNTIF(Registo!$B$2:$B$501,A39)) -> 0 | T39: =IF(OR(A39="",S39=0),"",LOOKUP(2,1/(Registo!$B$2:$B$501=A39),Registo!$E$2:$E$501)) | U39: Inclui agravamento por acesso condicionado (transporte manual 100 m + escadaria, 1.º andar s/ elevador)
A40: ARQ.34 | B40: Revestimento cerâmico em paredes de WC (fornecimento e aplicação), cimento-cola C2TES1 e betumação | C40: ARQ | D40: m² | I40: 52 | J40: =IF(AND(A40="",B40=""),"",IF(SUM(E40:H40)>0,SUM(E40:H40),I40)) -> 52 | K40: =IF(J40="","",ROUND(IF(SUM(E40:H40)>0,E40*(1+Config!$C$4)+F40*(1+Config!$C$5)+G40*(1+Config!$C$6)+H40*(1+Config!$C$7),I40*(1+Config!$C$8)),2)) -> 53.04 | M40: =IF(J40="","",IF(L40="",Config!$C$3,L40)) -> 0.2 | N40: =IF(K40="","",ROUND(K40*(1+M40),2)) -> 63.65 | O40: Orçamento próprio (custo, antes de margem) | P40: Ribeira – remodelação (L99) | Q40: 2026 | R40: B | S40: =IF(A40="","",COUNTIF(Registo!$B$2:$B$501,A40)) -> 0 | T40: =IF(OR(A40="",S40=0),"",LOOKUP(2,1/(Registo!$B$2:$B$501=A40),Registo!$E$2:$E$501)) | U40: Inclui agravamento por acesso condicionado (transporte manual 100 m + escadaria, 1.º andar s/ elevador)
A41: ARQ.35 | B41: Pladur hidrófugo H1 em zonas húmidas (paredes) | C41: ARQ | D41: m² | I41: 50 | J41: =IF(AND(A41="",B41=""),"",IF(SUM(E41:H41)>0,SUM(E41:H41),I41)) -> 50 | K41: =IF(J41="","",ROUND(IF(SUM(E41:H41)>0,E41*(1+Config!$C$4)+F41*(1+Config!$C$5)+G41*(1+Config!$C$6)+H41*(1+Config!$C$7),I41*(1+Config!$C$8)),2)) -> 51 | M41: =IF(J41="","",IF(L41="",Config!$C$3,L41)) -> 0.2 | N41: =IF(K41="","",ROUND(K41*(1+M41),2)) -> 61.2 | O41: Orçamento próprio (custo, antes de margem) | P41: Ribeira – remodelação (L99) | Q41: 2026 | R41: B | S41: =IF(A41="","",COUNTIF(Registo!$B$2:$B$501,A41)) -> 0 | T41: =IF(OR(A41="",S41=0),"",LOOKUP(2,1/(Registo!$B$2:$B$501=A41),Registo!$E$2:$E$501)) | U41: Inclui agravamento por acesso condicionado (transporte manual 100 m + escadaria, 1.º andar s/ elevador)
A42: ARQ.36 | B42: Impermeabilização com argamassa bicomponente (tipo Weber 824) em pavimento e zona de duche | C42: ARQ | D42: m² | I42: 28 | J42: =IF(AND(A42="",B42=""),"",IF(SUM(E42:H42)>0,SUM(E42:H42),I42)) -> 28 | K42: =IF(J42="","",ROUND(IF(SUM(E42:H42)>0,E42*(1+Config!$C$4)+F42*(1+Config!$C$5)+G42*(1+Config!$C$6)+H42*(1+Config!$C$7),I42*(1+Config!$C$8)),2)) -> 28.56 | M42: =IF(J42="","",IF(L42="",Config!$C$3,L42)) -> 0.2 | N42: =IF(K42="","",ROUND(K42*(1+M42),2)) -> 34.27 | O42: Orçamento próprio (custo, antes de margem) | P42: Ribeira – remodelação (L99) | Q42: 2026 | R42: B | S42: =IF(A42="","",COUNTIF(Registo!$B$2:$B$501,A42)) -> 0 | T42: =IF(OR(A42="",S42=0),"",LOOKUP(2,1/(Registo!$B$2:$B$501=A42),Registo!$E$2:$E$501)) | U42: Inclui agravamento por acesso condicionado (transporte manual 100 m + escadaria, 1.º andar s/ elevador)
A43: ARQ.37 | B43: Pavimento cerâmico em WC (fornecimento e aplicação), cimento-cola C2TES1 e betumação | C43: ARQ | D43: m² | I43: 52 | J43: =IF(AND(A43="",B43=""),"",IF(SUM(E43:H43)>0,SUM(E43:H43),I43)) -> 52 | K43: =IF(J43="","",ROUND(IF(SUM(E43:H43)>0,E43*(1+Config!$C$4)+F43*(1+Config!$C$5)+G43*(1+Config!$C$6)+H43*(1+Config!$C$7),I43*(1+Config!$C$8)),2)) -> 53.04 | M43: =IF(J43="","",IF(L43="",Config!$C$3,L43)) -> 0.2 | N43: =IF(K43="","",ROUND(K43*(1+M43),2)) -> 63.65 | O43: Orçamento próprio (custo, antes de margem) | P43: Ribeira – remodelação (L99) | Q43: 2026 | R43: B | S43: =IF(A43="","",COUNTIF(Registo!$B$2:$B$501,A43)) -> 0 | T43: =IF(OR(A43="",S43=0),"",LOOKUP(2,1/(Registo!$B$2:$B$501=A43),Registo!$E$2:$E$501)) | U43: Inclui agravamento por acesso condicionado (transporte manual 100 m + escadaria, 1.º andar s/ elevador)
A44: ARQ.38 | B44: Teto falso em pladur BA13 c/ estrutura suspensa, nivelamento e juntas | C44: ARQ | D44: m² | I44: 62 | J44: =IF(AND(A44="",B44=""),"",IF(SUM(E44:H44)>0,SUM(E44:H44),I44)) -> 62 | K44: =IF(J44="","",ROUND(IF(SUM(E44:H44)>0,E44*(1+Config!$C$4)+F44*(1+Config!$C$5)+G44*(1+Config!$C$6)+H44*(1+Config!$C$7),I44*(1+Config!$C$8)),2)) -> 63.24 | M44: =IF(J44="","",IF(L44="",Config!$C$3,L44)) -> 0.2 | N44: =IF(K44="","",ROUND(K44*(1+M44),2)) -> 75.89 | O44: Orçamento próprio (custo, antes de margem) | P44: Ribeira – remodelação (L99) | Q44: 2026 | R44: B | S44: =IF(A44="","",COUNTIF(Registo!$B$2:$B$501,A44)) -> 0 | T44: =IF(OR(A44="",S44=0),"",LOOKUP(2,1/(Registo!$B$2:$B$501=A44),Registo!$E$2:$E$501)) | U44: Inclui agravamento por acesso condicionado (transporte manual 100 m + escadaria, 1.º andar s/ elevador)
A45: ARQ.39 | B45: Teto falso em pladur hidrófugo H1 em zonas húmidas | C45: ARQ | D45: m² | I45: 55 | J45: =IF(AND(A45="",B45=""),"",IF(SUM(E45:H45)>0,SUM(E45:H45),I45)) -> 55 | K45: =IF(J45="","",ROUND(IF(SUM(E45:H45)>0,E45*(1+Config!$C$4)+F45*(1+Config!$C$5)+G45*(1+Config!$C$6)+H45*(1+Config!$C$7),I45*(1+Config!$C$8)),2)) -> 56.1 | M45: =IF(J45="","",IF(L45="",Config!$C$3,L45)) -> 0.2 | N45: =IF(K45="","",ROUND(K45*(1+M45),2)) -> 67.32 | O45: Orçamento próprio (custo, antes de margem) | P45: Ribeira – remodelação (L99) | Q45: 2026 | R45: B | S45: =IF(A45="","",COUNTIF(Registo!$B$2:$B$501,A45)) -> 0 | T45: =IF(OR(A45="",S45=0),"",LOOKUP(2,1/(Registo!$B$2:$B$501=A45),Registo!$E$2:$E$501)) | U45: Inclui agravamento por acesso condicionado (transporte manual 100 m + escadaria, 1.º andar s/ elevador)
A46: ARQ.40 | B46: Pintura de paredes e tetos: primário + 2 demãos de tinta acrílica lavável | C46: ARQ | D46: m² | I46: 20 | J46: =IF(AND(A46="",B46=""),"",IF(SUM(E46:H46)>0,SUM(E46:H46),I46)) -> 20 | K46: =IF(J46="","",ROUND(IF(SUM(E46:H46)>0,E46*(1+Config!$C$4)+F46*(1+Config!$C$5)+G46*(1+Config!$C$6)+H46*(1+Config!$C$7),I46*(1+Config!$C$8)),2)) -> 20.4 | M46: =IF(J46="","",IF(L46="",Config!$C$3,L46)) -> 0.2 | N46: =IF(K46="","",ROUND(K46*(1+M46),2)) -> 24.48 | O46: Orçamento próprio (custo, antes de margem) | P46: Ribeira – remodelação (L99) | Q46: 2026 | R46: B | S46: =IF(A46="","",COUNTIF(Registo!$B$2:$B$501,A46)) -> 0 | T46: =IF(OR(A46="",S46=0),"",LOOKUP(2,1/(Registo!$B$2:$B$501=A46),Registo!$E$2:$E$501)) | U46: Inclui agravamento por acesso condicionado (transporte manual 100 m + escadaria, 1.º andar s/ elevador)
A47: ARQ.41 | B47: OSB 10 mm para reforço da base de pavimento flutuante | C47: ARQ | D47: m² | I47: 48 | J47: =IF(AND(A47="",B47=""),"",IF(SUM(E47:H47)>0,SUM(E47:H47),I47)) -> 48 | K47: =IF(J47="","",ROUND(IF(SUM(E47:H47)>0,E47*(1+Config!$C$4)+F47*(1+Config!$C$5)+G47*(1+Config!$C$6)+H47*(1+Config!$C$7),I47*(1+Config!$C$8)),2)) -> 48.96 | M47: =IF(J47="","",IF(L47="",Config!$C$3,L47)) -> 0.2 | N47: =IF(K47="","",ROUND(K47*(1+M47),2)) -> 58.75 | O47: Orçamento próprio (custo, antes de margem) | P47: Ribeira – remodelação (L99) | Q47: 2026 | R47: B | S47: =IF(A47="","",COUNTIF(Registo!$B$2:$B$501,A47)) -> 0 | T47: =IF(OR(A47="",S47=0),"",LOOKUP(2,1/(Registo!$B$2:$B$501=A47),Registo!$E$2:$E$501)) | U47: Inclui agravamento por acesso condicionado (transporte manual 100 m + escadaria, 1.º andar s/ elevador)
A48: ARQ.42 | B48: Pavimento laminado AC4 Classe 32, 8 mm, click, c/ manta acústica e remates | C48: ARQ | D48: m² | I48: 54 | J48: =IF(AND(A48="",B48=""),"",IF(SUM(E48:H48)>0,SUM(E48:H48),I48)) -> 54 | K48: =IF(J48="","",ROUND(IF(SUM(E48:H48)>0,E48*(1+Config!$C$4)+F48*(1+Config!$C$5)+G48*(1+Config!$C$6)+H48*(1+Config!$C$7),I48*(1+Config!$C$8)),2)) -> 55.08 | M48: =IF(J48="","",IF(L48="",Config!$C$3,L48)) -> 0.2 | N48: =IF(K48="","",ROUND(K48*(1+M48),2)) -> 66.1 | O48: Orçamento próprio (custo, antes de margem) | P48: Ribeira – remodelação (L99) | Q48: 2026 | R48: B | S48: =IF(A48="","",COUNTIF(Registo!$B$2:$B$501,A48)) -> 0 | T48: =IF(OR(A48="",S48=0),"",LOOKUP(2,1/(Registo!$B$2:$B$501=A48),Registo!$E$2:$E$501)) | U48: Inclui agravamento por acesso condicionado (transporte manual 100 m + escadaria, 1.º andar s/ elevador)
A49: EST.01 | B49: Betão de limpeza C12/15 | C49: EST | D49: m³ | I49: 95 | J49: =IF(AND(A49="",B49=""),"",IF(SUM(E49:H49)>0,SUM(E49:H49),I49)) -> 95 | K49: =IF(J49="","",ROUND(IF(SUM(E49:H49)>0,E49*(1+Config!$C$4)+F49*(1+Config!$C$5)+G49*(1+Config!$C$6)+H49*(1+Config!$C$7),I49*(1+Config!$C$8)),2)) -> 96.9 | M49: =IF(J49="","",IF(L49="",Config!$C$3,L49)) -> 0.2 | N49: =IF(K49="","",ROUND(K49*(1+M49),2)) -> 116.28 | O49: Referência de mercado Porto/Aveiro (BASE_PRECOS_2026) | Q49: Jun-2026 | R49: C | S49: =IF(A49="","",COUNTIF(Registo!$B$2:$B$501,A49)) -> 0 | T49: =IF(OR(A49="",S49=0),"",LOOKUP(2,1/(Registo!$B$2:$B$501=A49),Registo!$E$2:$E$501))
A50: EST.02 | B50: Betão em fundações C25/30 (exec. c/ bomba) | C50: EST | D50: m³ | I50: 145 | J50: =IF(AND(A50="",B50=""),"",IF(SUM(E50:H50)>0,SUM(E50:H50),I50)) -> 145 | K50: =IF(J50="","",ROUND(IF(SUM(E50:H50)>0,E50*(1+Config!$C$4)+F50*(1+Config!$C$5)+G50*(1+Config!$C$6)+H50*(1+Config!$C$7),I50*(1+Config!$C$8)),2)) -> 147.9 | M50: =IF(J50="","",IF(L50="",Config!$C$3,L50)) -> 0.2 | N50: =IF(K50="","",ROUND(K50*(1+M50),2)) -> 177.48 | O50: Referência de mercado Porto/Aveiro (BASE_PRECOS_2026) | Q50: Jun-2026 | R50: C | S50: =IF(A50="","",COUNTIF(Registo!$B$2:$B$501,A50)) -> 0 | T50: =IF(OR(A50="",S50=0),"",LOOKUP(2,1/(Registo!$B$2:$B$501=A50),Registo!$E$2:$E$501))
A51: EST.03 | B51: Betão em pilares C25/30 | C51: EST | D51: m³ | I51: 165 | J51: =IF(AND(A51="",B51=""),"",IF(SUM(E51:H51)>0,SUM(E51:H51),I51)) -> 165 | K51: =IF(J51="","",ROUND(IF(SUM(E51:H51)>0,E51*(1+Config!$C$4)+F51*(1+Config!$C$5)+G51*(1+Config!$C$6)+H51*(1+Config!$C$7),I51*(1+Config!$C$8)),2)) -> 168.3 | M51: =IF(J51="","",IF(L51="",Config!$C$3,L51)) -> 0.2 | N51: =IF(K51="","",ROUND(K51*(1+M51),2)) -> 201.96 | O51: Referência de mercado Porto/Aveiro (BASE_PRECOS_2026) | Q51: Jun-2026 | R51: C | S51: =IF(A51="","",COUNTIF(Registo!$B$2:$B$501,A51)) -> 0 | T51: =IF(OR(A51="",S51=0),"",LOOKUP(2,1/(Registo!$B$2:$B$501=A51),Registo!$E$2:$E$501))
A52: EST.04 | B52: Betão em vigas C25/30 | C52: EST | D52: m³ | I52: 155 | J52: =IF(AND(A52="",B52=""),"",IF(SUM(E52:H52)>0,SUM(E52:H52),I52)) -> 155 | K52: =IF(J52="","",ROUND(IF(SUM(E52:H52)>0,E52*(1+Config!$C$4)+F52*(1+Config!$C$5)+G52*(1+Config!$C$6)+H52*(1+Config!$C$7),I52*(1+Config!$C$8)),2)) -> 158.1 | M52: =IF(J52="","",IF(L52="",Config!$C$3,L52)) -> 0.2 | N52: =IF(K52="","",ROUND(K52*(1+M52),2)) -> 189.72 | O52: Referência de mercado Porto/Aveiro (BASE_PRECOS_2026) | Q52: Jun-2026 | R52: C | S52: =IF(A52="","",COUNTIF(Registo!$B$2:$B$501,A52)) -> 0 | T52: =IF(OR(A52="",S52=0),"",LOOKUP(2,1/(Registo!$B$2:$B$501=A52),Registo!$E$2:$E$501))
A53: EST.05 | B53: Betão em laje maciça C25/30 | C53: EST | D53: m³ | I53: 150 | J53: =IF(AND(A53="",B53=""),"",IF(SUM(E53:H53)>0,SUM(E53:H53),I53)) -> 150 | K53: =IF(J53="","",ROUND(IF(SUM(E53:H53)>0,E53*(1+Config!$C$4)+F53*(1+Config!$C$5)+G53*(1+Config!$C$6)+H53*(1+Config!$C$7),I53*(1+Config!$C$8)),2)) -> 153 | M53: =IF(J53="","",IF(L53="",Config!$C$3,L53)) -> 0.2 | N53: =IF(K53="","",ROUND(K53*(1+M53),2)) -> 183.6 | O53: Referência de mercado Porto/Aveiro (BASE_PRECOS_2026) | Q53: Jun-2026 | R53: C | S53: =IF(A53="","",COUNTIF(Registo!$B$2:$B$501,A53)) -> 0 | T53: =IF(OR(A53="",S53=0),"",LOOKUP(2,1/(Registo!$B$2:$B$501=A53),Registo!$E$2:$E$501))
A54: EST.06 | B54: Betão em laje aligeirada (PAVICER) C25/30 | C54: EST | D54: m² | I54: 62 | J54: =IF(AND(A54="",B54=""),"",IF(SUM(E54:H54)>0,SUM(E54:H54),I54)) -> 62 | K54: =IF(J54="","",ROUND(IF(SUM(E54:H54)>0,E54*(1+Config!$C$4)+F54*(1+Config!$C$5)+G54*(1+Config!$C$6)+H54*(1+Config!$C$7),I54*(1+Config!$C$8)),2)) -> 63.24 | M54: =IF(J54="","",IF(L54="",Config!$C$3,L54)) -> 0.2 | N54: =IF(K54="","",ROUND(K54*(1+M54),2)) -> 75.89 | O54: Referência de mercado Porto/Aveiro (BASE_PRECOS_2026) | Q54: Jun-2026 | R54: C | S54: =IF(A54="","",COUNTIF(Registo!$B$2:$B$501,A54)) -> 0 | T54: =IF(OR(A54="",S54=0),"",LOOKUP(2,1/(Registo!$B$2:$B$501=A54),Registo!$E$2:$E$501))
A55: EST.07 | B55: Betão em escadas C25/30 | C55: EST | D55: m³ | I55: 175 | J55: =IF(AND(A55="",B55=""),"",IF(SUM(E55:H55)>0,SUM(E55:H55),I55)) -> 175 | K55: =IF(J55="","",ROUND(IF(SUM(E55:H55)>0,E55*(1+Config!$C$4)+F55*(1+Config!$C$5)+G55*(1+Config!$C$6)+H55*(1+Config!$C$7),I55*(1+Config!$C$8)),2)) -> 178.5 | M55: =IF(J55="","",IF(L55="",Config!$C$3,L55)) -> 0.2 | N55: =IF(K55="","",ROUND(K55*(1+M55),2)) -> 214.2 | O55: Referência de mercado Porto/Aveiro (BASE_PRECOS_2026) | Q55: Jun-2026 | R55: C | S55: =IF(A55="","",COUNTIF(Registo!$B$2:$B$501,A55)) -> 0 | T55: =IF(OR(A55="",S55=0),"",LOOKUP(2,1/(Registo!$B$2:$B$501=A55),Registo!$E$2:$E$501))
A56: EST.08 | B56: Aço A400 em varão (fornecimento + colocação) | C56: EST | D56: kg | I56: 1.45 | J56: =IF(AND(A56="",B56=""),"",IF(SUM(E56:H56)>0,SUM(E56:H56),I56)) -> 1.45 | K56: =IF(J56="","",ROUND(IF(SUM(E56:H56)>0,E56*(1+Config!$C$4)+F56*(1+Config!$C$5)+G56*(1+Config!$C$6)+H56*(1+Config!$C$7),I56*(1+Config!$C$8)),2)) -> 1.48 | M56: =IF(J56="","",IF(L56="",Config!$C$3,L56)) -> 0.2 | N56: =IF(K56="","",ROUND(K56*(1+M56),2)) -> 1.78 | O56: Referência de mercado Porto/Aveiro (BASE_PRECOS_2026) | Q56: Jun-2026 | R56: C | S56: =IF(A56="","",COUNTIF(Registo!$B$2:$B$501,A56)) -> 0 | T56: =IF(OR(A56="",S56=0),"",LOOKUP(2,1/(Registo!$B$2:$B$501=A56),Registo!$E$2:$E$501))
A57: EST.09 | B57: Aço A500 em varão (fornecimento + colocação) | C57: EST | D57: kg | I57: 1.55 | J57: =IF(AND(A57="",B57=""),"",IF(SUM(E57:H57)>0,SUM(E57:H57),I57)) -> 1.55 | K57: =IF(J57="","",ROUND(IF(SUM(E57:H57)>0,E57*(1+Config!$C$4)+F57*(1+Config!$C$5)+G57*(1+Config!$C$6)+H57*(1+Config!$C$7),I57*(1+Config!$C$8)),2)) -> 1.58 | M57: =IF(J57="","",IF(L57="",Config!$C$3,L57)) -> 0.2 | N57: =IF(K57="","",ROUND(K57*(1+M57),2)) -> 1.9 | O57: Referência de mercado Porto/Aveiro (BASE_PRECOS_2026) | Q57: Jun-2026 | R57: C | S57: =IF(A57="","",COUNTIF(Registo!$B$2:$B$501,A57)) -> 0 | T57: =IF(OR(A57="",S57=0),"",LOOKUP(2,1/(Registo!$B$2:$B$501=A57),Registo!$E$2:$E$501))
A58: EST.10 | B58: Cofragem recuperável em pilares | C58: EST | D58: m² | I58: 22 | J58: =IF(AND(A58="",B58=""),"",IF(SUM(E58:H58)>0,SUM(E58:H58),I58)) -> 22 | K58: =IF(J58="","",ROUND(IF(SUM(E58:H58)>0,E58*(1+Config!$C$4)+F58*(1+Config!$C$5)+G58*(1+Config!$C$6)+H58*(1+Config!$C$7),I58*(1+Config!$C$8)),2)) -> 22.44 | M58: =IF(J58="","",IF(L58="",Config!$C$3,L58)) -> 0.2 | N58: =IF(K58="","",ROUND(K58*(1+M58),2)) -> 26.93 | O58: Referência de mercado Porto/Aveiro (BASE_PRECOS_2026) | Q58: Jun-2026 | R58: C | S58: =IF(A58="","",COUNTIF(Registo!$B$2:$B$501,A58)) -> 0 | T58: =IF(OR(A58="",S58=0),"",LOOKUP(2,1/(Registo!$B$2:$B$501=A58),Registo!$E$2:$E$501))
...

Sheet Config
B1: PARÂMETROS
B3: Margem padrão (sobre o custo) | C3: 0.2 | D3: Igual à folha _Produção_Folha_de_orçamento.xlsx (célula I6)
B4: Encargos – Mão de obra | C4: 0.01 | D4: Folha de orçamento, célula J6
B5: Encargos – Materiais | C5: 0.03 | D5: Folha de orçamento, célula K6
B6: Encargos – Equipamento | C6: 0.02 | D6: Folha de orçamento, célula L6
B7: Encargos – Subempreitada | C7: 0.02 | D7: Folha de orçamento, célula M6
B8: Encargo médio – preço global | C8: 0.02 | D8: Pressuposto: média aplicada a artigos ainda não decompostos – ajustar
B9: IVA – taxa normal | C9: 0.23 | D9: Referência
B10: IVA – taxa reduzida (ARU / reabilitação) | C10: 0.06 | D10: Referência – confirmar enquadramento em cada obra
B13: ESPECIALIDADES
B14: GER | C14: Gerais / Estaleiro
B15: ARQ | C15: Arquitetura
B16: EST | C16: Estruturas
B17: HID | C17: Águas (abastecimento)
B18: PLU | C18: Águas pluviais
B19: ESG | C19: Esgotos
B20: ELE | C20: Eletricidade
B21: ITED | C21: ITED
B22: AVAC | C22: AVAC / Ventilação
B23: GAS | C23: Gás
B24: SCIE | C24: SCIE
B25: TERM | C25: Térmica
... B27: CARP | C27: Carpintarias / Mobiliário

Sheet Registo
A1: Data | B1: Cód. | C1: Obra | D1: Fonte (fornecedor / subempreiteiro / documento) | E1: Preço unitário (€) | F1: Fiabilidade | G1: Observações
