Workbook

Sheet Instruções
B1: Checklist de Omissões e Compatibilização de Projetos
B2: Moradias e remodelações · v1.0 · Ponto de partida para validação e enriquecimento pelo utilizador
B3: DADOS DA OBRA
B4: Obra
B5: Tipo de obra | D5: ← escolha da lista: filtra automaticamente os pontos aplicáveis (coluna I da Checklist)
B6: Revisão do projeto analisada
B7: Data da análise
B8: Analisado por
B10: COMO USAR (passo a passo)
B11: 1. Dados da obra | C11: Preencha as células amarelas acima. O «Tipo de obra» marca como «Não» os pontos que só se aplicam ao outro tipo.
B12: 2. Filtrar | C12: Na Checklist, filtre a coluna I = «Sim». Trabalhe por especialidade (coluna B).
B13: 3. Verificar | C13: Para cada ponto, consulte a peça indicada em «Onde verificar» e escolha o Estado (coluna J).
B14: 4. Rastrear | C14: Para cada «Omisso» ou «A esclarecer», preencha o capítulo/artigo do MQ (K), o desenho/peça (L) e a ação proposta (M).
B15: 5. Valorizar | C15: Opcional: estime o valor da omissão (N) para medir o impacto no orçamento.
B16: 6. Resumo | C16: A folha «Resumo» calcula o progresso e as omissões por especialidade e por natureza.
B18: CÉLULAS A PREENCHER
B19: Fundo amarelo | C19: Únicas células de introdução de dados (Dados da obra e colunas J a N da Checklist). As restantes colunas são a base da checklist ou fórmulas.
B21: ESTADOS (coluna J)
B22: OK | C22: Verificado e completo no projeto e no MQ.
B23: Omisso | C23: Falta no MQ, falta definição no projeto ou há incompatibilidade confirmada.
B24: A esclarecer | C24: Dúvida a colocar ao projetista (pedido de esclarecimento).
B25: N/A | C25: Não se aplica a esta obra em concreto.
B26: (vazio) | C26: Ainda por verificar.
B28: NATUREZA (coluna G)
B29: Omissão no MQ | C29: O trabalho é necessário mas pode não ter artigo no mapa de quantidades.
B30: Omissão de projeto | C30: Falta uma definição técnica, peça desenhada ou estudo.
B31: Compatibilização | C31: Interface entre especialidades: verificar que as peças dizem o mesmo e não colidem.
B33: GRAVIDADE TÍPICA (coluna H)
B34: Alta | C34: Impacto relevante no custo, no prazo ou no desempenho/segurança, ou retrabalho difícil.
B35: Média | C35: Impacto moderado, resolúvel em obra com custo controlado.
B36: Baixa | C36: Impacto reduzido ou facilmente absorvido.
C37: A gravidade é indicativa: ajuste-a caso a caso no campo de observações.
B39: EXEMPLO DE LINHA PREENCHIDA
B40: ID | C40: ARQ-13
B41: Ponto de verificação | C41: Zonas de duche, bases de banheira e pavimentos de casas de banho
B42: Estado | C42: Omisso
B43: Capítulo/Artigo MQ | C43: Cap. 7 – Revestimentos (sem artigo)
B44: Desenho/Peça | C44: ARQ-05 Rev.B – Planta piso 1
B45: Observações / Ação proposta | C45: Sem artigo de impermeabilização sob duches à face; pedir artigo ao projetista e confirmar rebaixo na EST-03.
B46: Valor estimado (€) | C46: 450
...

Sheet Resumo
A1: RESUMO DA VERIFICAÇÃO
A2: ="Obra: "&IF(Instruções!$C$4="","(preencher em Instruções)",Instruções!$C$4)&" · Tipo: "&IF(Instruções!$C$5="","(todos os pontos)",Instruções!$C$5) -> Obra: (preencher em Instruções) · Tipo: (todos os pontos)
A4: Especialidade | B4: Pontos aplicáveis | C4: OK | D4: Omisso | E4: A esclarecer | F4: N/A | G4: Por verificar | H4: % verificado | I4: Omissões gravidade Alta | J4: Valor estimado (€)
A5: Gerais e Estaleiro | B5: =COUNTIFS(Checklist!$B$4:$B$221,$A5,Checklist!$I$4:$I$221,"Sim") -> 13 | C5: =COUNTIFS(Checklist!$B$4:$B$221,$A5,Checklist!$I$4:$I$221,"Sim",Checklist!$J$4:$J$221,"OK") -> 0 | D5: =COUNTIFS(Checklist!$B$4:$B$221,$A5,Checklist!$I$4:$I$221,"Sim",Checklist!$J$4:$J$221,"Omisso") -> 0 | E5: =COUNTIFS(Checklist!$B$4:$B$221,$A5,Checklist!$I$4:$I$221,"Sim",Checklist!$J$4:$J$221,"A esclarecer") -> 0 | F5: =COUNTIFS(Checklist!$B$4:$B$221,$A5,Checklist!$I$4:$I$221,"Sim",Checklist!$J$4:$J$221,"N/A") -> 0 | G5: =B5-SUM(C5:F5) -> 13 | H5: =IF(B5=0,"-",(B5-G5)/B5) -> 0 | I5: =COUNTIFS(Checklist!$B$4:$B$221,$A5,Checklist!$I$4:$I$221,"Sim",Checklist!$J$4:$J$221,"Omisso",Checklist!$H$4:$H$221,"Alta") -> 0 | J5: =SUMIFS(Checklist!$N$4:$N$221,Checklist!$B$4:$B$221,$A5,Checklist!$I$4:$I$221,"Sim") -> 0
A6: Demolições e Trabalhos Preparatórios | B6: =COUNTIFS(Checklist!$B$4:$B$221,$A6,Checklist!$I$4:$I$221,"Sim") -> 11 | C6: =COUNTIFS(Checklist!$B$4:$B$221,$A6,Checklist!$I$4:$I$221,"Sim",Checklist!$J$4:$J$221,"OK") -> 0 | D6: =COUNTIFS(Checklist!$B$4:$B$221,$A6,Checklist!$I$4:$I$221,"Sim",Checklist!$J$4:$J$221,"Omisso") -> 0 | E6: =COUNTIFS(Checklist!$B$4:$B$221,$A6,Checklist!$I$4:$I$221,"Sim",Checklist!$J$4:$J$221,"A esclarecer") -> 0 | F6: =COUNTIFS(Checklist!$B$4:$B$221,$A6,Checklist!$I$4:$I$221,"Sim",Checklist!$J$4:$J$221,"N/A") -> 0 | G6: =B6-SUM(C6:F6) -> 11 | H6: =IF(B6=0,"-",(B6-G6)/B6) -> 0 | I6: =COUNTIFS(Checklist!$B$4:$B$221,$A6,Checklist!$I$4:$I$221,"Sim",Checklist!$J$4:$J$221,"Omisso",Checklist!$H$4:$H$221,"Alta") -> 0 | J6: =SUMIFS(Checklist!$N$4:$N$221,Checklist!$B$4:$B$221,$A6,Checklist!$I$4:$I$221,"Sim") -> 0
A7: Movimento de Terras e Fundações | B7: =COUNTIFS(Checklist!$B$4:$B$221,$A7,Checklist!$I$4:$I$221,"Sim") -> 11 | C7: =COUNTIFS(Checklist!$B$4:$B$221,$A7,Checklist!$I$4:$I$221,"Sim",Checklist!$J$4:$J$221,"OK") -> 0 | D7: =COUNTIFS(Checklist!$B$4:$B$221,$A7,Checklist!$I$4:$I$221,"Sim",Checklist!$J$4:$J$221,"Omisso") -> 0 | E7: =COUNTIFS(Checklist!$B$4:$B$221,$A7,Checklist!$I$4:$I$221,"Sim",Checklist!$J$4:$J$221,"A esclarecer") -> 0 | F7: =COUNTIFS(Checklist!$B$4:$B$221,$A7,Checklist!$I$4:$I$221,"Sim",Checklist!$J$4:$J$221,"N/A") -> 0 | G7: =B7-SUM(C7:F7) -> 11 | H7: =IF(B7=0,"-",(B7-G7)/B7) -> 0 | I7: =COUNTIFS(Checklist!$B$4:$B$221,$A7,Checklist!$I$4:$I$221,"Sim",Checklist!$J$4:$J$221,"Omisso",Checklist!$H$4:$H$221,"Alta") -> 0 | J7: =SUMIFS(Checklist!$N$4:$N$221,Checklist!$B$4:$B$221,$A7,Checklist!$I$4:$I$221,"Sim") -> 0
A8: Estruturas | B8: =COUNTIFS(Checklist!$B$4:$B$221,$A8,Checklist!$I$4:$I$221,"Sim") -> 18 | C8: =COUNTIFS(Checklist!$B$4:$B$221,$A8,Checklist!$I$4:$I$221,"Sim",Checklist!$J$4:$J$221,"OK") -> 0 | D8: =COUNTIFS(Checklist!$B$4:$B$221,$A8,Checklist!$I$4:$I$221,"Sim",Checklist!$J$4:$J$221,"Omisso") -> 0 | E8: =COUNTIFS(Checklist!$B$4:$B$221,$A8,Checklist!$I$4:$I$221,"Sim",Checklist!$J$4:$J$221,"A esclarecer") -> 0 | F8: =COUNTIFS(Checklist!$B$4:$B$221,$A8,Checklist!$I$4:$I$221,"Sim",Checklist!$J$4:$J$221,"N/A") -> 0 | G8: =B8-SUM(C8:F8) -> 18 | H8: =IF(B8=0,"-",(B8-G8)/B8) -> 0 | I8: =COUNTIFS(Checklist!$B$4:$B$221,$A8,Checklist!$I$4:$I$221,"Sim",Checklist!$J$4:$J$221,"Omisso",Checklist!$H$4:$H$221,"Alta") -> 0 | J8: =SUMIFS(Checklist!$N$4:$N$221,Checklist!$B$4:$B$221,$A8,Checklist!$I$4:$I$221,"Sim") -> 0
A9: Arquitetura | B9: =COUNTIFS(Checklist!$B$4:$B$221,$A9,Checklist!$I$4:$I$221,"Sim") -> 42 | C9: =COUNTIFS(Checklist!$B$4:$B$221,$A9,Checklist!$I$4:$I$221,"Sim",Checklist!$J$4:$J$221,"OK") -> 0 | D9: =COUNTIFS(Checklist!$B$4:$B$221,$A9,Checklist!$I$4:$I$221,"Sim",Checklist!$J$4:$J$221,"Omisso") -> 0 | E9: =COUNTIFS(Checklist!$B$4:$B$221,$A9,Checklist!$I$4:$I$221,"Sim",Checklist!$J$4:$J$221,"A esclarecer") -> 0 | F9: =COUNTIFS(Checklist!$B$4:$B$221,$A9,Checklist!$I$4:$I$221,"Sim",Checklist!$J$4:$J$221,"N/A") -> 0 | G9: =B9-SUM(C9:F9) -> 42 | H9: =IF(B9=0,"-",(B9-G9)/B9) -> 0 | I9: =COUNTIFS(Checklist!$B$4:$B$221,$A9,Checklist!$I$4:$I$221,"Sim",Checklist!$J$4:$J$221,"Omisso",Checklist!$H$4:$H$221,"Alta") -> 0 | J9: =SUMIFS(Checklist!$N$4:$N$221,Checklist!$B$4:$B$221,$A9,Checklist!$I$4:$I$221,"Sim") -> 0
A10: Águas (Abastecimento) | B10: =COUNTIFS(Checklist!$B$4:$B$221,$A10,Checklist!$I$4:$I$221,"Sim") -> 11 | C10: =COUNTIFS(Checklist!$B$4:$B$221,$A10,Checklist!$I$4:$I$221,"Sim",Checklist!$J$4:$J$221,"OK") -> 0 | D10: =COUNTIFS(Checklist!$B$4:$B$221,$A10,Checklist!$I$4:$I$221,"Sim",Checklist!$J$4:$J$221,"Omisso") -> 0 | E10: =COUNTIFS(Checklist!$B$4:$B$221,$A10,Checklist!$I$4:$I$221,"Sim",Checklist!$J$4:$J$221,"A esclarecer") -> 0 | F10: =COUNTIFS(Checklist!$B$4:$B$221,$A10,Checklist!$I$4:$I$221,"Sim",Checklist!$J$4:$J$221,"N/A") -> 0 | G10: =B10-SUM(C10:F10) -> 11 | H10: =IF(B10=0,"-",(B10-G10)/B10) -> 0 | I10: =COUNTIFS(Checklist!$B$4:$B$221,$A10,Checklist!$I$4:$I$221,"Sim",Checklist!$J$4:$J$221,"Omisso",Checklist!$H$4:$H$221,"Alta") -> 0 | J10: =SUMIFS(Checklist!$N$4:$N$221,Checklist!$B$4:$B$221,$A10,Checklist!$I$4:$I$221,"Sim") -> 0
A11: Esgotos Domésticos | B11: =COUNTIFS(Checklist!$B$4:$B$221,$A11,Checklist!$I$4:$I$221,"Sim") -> 11 | C11: =COUNTIFS(Checklist!$B$4:$B$221,$A11,Checklist!$I$4:$I$221,"Sim",Checklist!$J$4:$J$221,"OK") -> 0 | D11: =COUNTIFS(Checklist!$B$4:$B$221,$A11,Checklist!$I$4:$I$221,"Sim",Checklist!$J$4:$J$221,"Omisso") -> 0 | E11: =COUNTIFS(Checklist!$B$4:$B$221,$A11,Checklist!$I$4:$I$221,"Sim",Checklist!$J$4:$J$221,"A esclarecer") -> 0 | F11: =COUNTIFS(Checklist!$B$4:$B$221,$A11,Checklist!$I$4:$I$221,"Sim",Checklist!$J$4:$J$221,"N/A") -> 0 | G11: =B11-SUM(C11:F11) -> 11 | H11: =IF(B11=0,"-",(B11-G11)/B11) -> 0 | I11: =COUNTIFS(Checklist!$B$4:$B$221,$A11,Checklist!$I$4:$I$221,"Sim",Checklist!$J$4:$J$221,"Omisso",Checklist!$H$4:$H$221,"Alta") -> 0 | J11: =SUMIFS(Checklist!$N$4:$N$221,Checklist!$B$4:$B$221,$A11,Checklist!$I$4:$I$221,"Sim") -> 0
A12: Águas Pluviais | B12: =COUNTIFS(Checklist!$B$4:$B$221,$A12,Checklist!$I$4:$I$221,"Sim") -> 8 | C12: =COUNTIFS(Checklist!$B$4:$B$221,$A12,Checklist!$I$4:$I$221,"Sim",Checklist!$J$4:$J$221,"OK") -> 0 | D12: =COUNTIFS(Checklist!$B$4:$B$221,$A12,Checklist!$I$4:$I$221,"Sim",Checklist!$J$4:$J$221,"Omisso") -> 0 | E12: =COUNTIFS(Checklist!$B$4:$B$221,$A12,Checklist!$I$4:$I$221,"Sim",Checklist!$J$4:$J$221,"A esclarecer") -> 0 | F12: =COUNTIFS(Checklist!$B$4:$B$221,$A12,Checklist!$I$4:$I$221,"Sim",Checklist!$J$4:$J$221,"N/A") -> 0 | G12: =B12-SUM(C12:F12) -> 8 | H12: =IF(B12=0,"-",(B12-G12)/B12) -> 0 | I12: =COUNTIFS(Checklist!$B$4:$B$221,$A12,Checklist!$I$4:$I$221,"Sim",Checklist!$J$4:$J$221,"Omisso",Checklist!$H$4:$H$221,"Alta") -> 0 | J12: =SUMIFS(Checklist!$N$4:$N$221,Checklist!$B$4:$B$221,$A12,Checklist!$I$4:$I$221,"Sim") -> 0
A13: Eletricidade | B13: =COUNTIFS(Checklist!$B$4:$B$221,$A13,Checklist!$I$4:$I$221,"Sim") -> 15 | C13: =COUNTIFS(Checklist!$B$4:$B$221,$A13,Checklist!$I$4:$I$221,"Sim",Checklist!$J$4:$J$221,"OK") -> 0 | D13: =COUNTIFS(Checklist!$B$4:$B$221,$A13,Checklist!$I$4:$I$221,"Sim",Checklist!$J$4:$J$221,"Omisso") -> 0 | E13: =COUNTIFS(Checklist!$B$4:$B$221,$A13,Checklist!$I$4:$I$221,"Sim",Checklist!$J$4:$J$221,"A esclarecer") -> 0 | F13: =COUNTIFS(Checklist!$B$4:$B$221,$A13,Checklist!$I$4:$I$221,"Sim",Checklist!$J$4:$J$221,"N/A") -> 0 | G13: =B13-SUM(C13:F13) -> 15 | H13: =IF(B13=0,"-",(B13-G13)/B13) -> 0 | I13: =COUNTIFS(Checklist!$B$4:$B$221,$A13,Checklist!$I$4:$I$221,"Sim",Checklist!$J$4:$J$221,"Omisso",Checklist!$H$4:$H$221,"Alta") -> 0 | J13: =SUMIFS(Checklist!$N$4:$N$221,Checklist!$B$4:$B$221,$A13,Checklist!$I$4:$I$221,"Sim") -> 0
A14: ITED | B14: =COUNTIFS(Checklist!$B$4:$B$221,$A14,Checklist!$I$4:$I$221,"Sim") -> 5 | C14: =COUNTIFS(Checklist!$B$4:$B$221,$A14,Checklist!$I$4:$I$221,"Sim",Checklist!$J$4:$J$221,"OK") -> 0 | D14: =COUNTIFS(Checklist!$B$4:$B$221,$A14,Checklist!$I$4:$I$221,"Sim",Checklist!$J$4:$J$221,"Omisso") -> 0 | E14: =COUNTIFS(Checklist!$B$4:$B$221,$A14,Checklist!$I$4:$I$221,"Sim",Checklist!$J$4:$J$221,"A esclarecer") -> 0 | F14: =COUNTIFS(Checklist!$B$4:$B$221,$A14,Checklist!$I$4:$I$221,"Sim",Checklist!$J$4:$J$221,"N/A") -> 0 | G14: =B14-SUM(C14:F14) -> 5 | H14: =IF(B14=0,"-",(B14-G14)/B14) -> 0 | I14: =COUNTIFS(Checklist!$B$4:$B$221,$A14,Checklist!$I$4:$I$221,"Sim",Checklist!$J$4:$J$221,"Omisso",Checklist!$H$4:$H$221,"Alta") -> 0 | J14: =SUMIFS(Checklist!$N$4:$N$221,Checklist!$B$4:$B$221,$A14,Checklist!$I$4:$I$221,"Sim") -> 0
A15: Gás | B15: =COUNTIFS(Checklist!$B$4:$B$221,$A15,Checklist!$I$4:$I$221,"Sim") -> 5 | C15: =COUNTIFS(Checklist!$B$4:$B$221,$A15,Checklist!$I$4:$I$221,"Sim",Checklist!$J$4:$J$221,"OK") -> 0 | D15: =COUNTIFS(Checklist!$B$4:$B$221,$A15,Checklist!$I$4:$I$221,"Sim",Checklist!$J$4:$J$221,"Omisso") -> 0 | E15: =COUNTIFS(Checklist!$B$4:$B$221,$A15,Checklist!$I$4:$I$221,"Sim",Checklist!$J$4:$J$221,"A esclarecer") -> 0 | F15: =COUNTIFS(Checklist!$B$4:$B$221,$A15,Checklist!$I$4:$I$221,"Sim",Checklist!$J$4:$J$221,"N/A") -> 0 | G15: =B15-SUM(C15:F15) -> 5 | H15: =IF(B15=0,"-",(B15-G15)/B15) -> 0 | I15: =COUNTIFS(Checklist!$B$4:$B$221,$A15,Checklist!$I$4:$I$221,"Sim",Checklist!$J$4:$J$221,"Omisso",Checklist!$H$4:$H$221,"Alta") -> 0 | J15: =SUMIFS(Checklist!$N$4:$N$221,Checklist!$B$4:$B$221,$A15,Checklist!$I$4:$I$221,"Sim") -> 0
A16: AVAC e Ventilação | B16: =COUNTIFS(Checklist!$B$4:$B$221,$A16,Checklist!$I$4:$I$221,"Sim") -> 11 | C16: =COUNTIFS(Checklist!$B$4:$B$221,$A16,Checklist!$I$4:$I$221,"Sim",Checklist!$J$4:$J$221,"OK") -> 0 | D16: =COUNTIFS(Checklist!$B$4:$B$221,$A16,Checklist!$I$4:$I$221,"Sim",Checklist!$J$4:$J$221,"Omisso") -> 0 | E16: =COUNTIFS(Checklist!$B$4:$B$221,$A16,Checklist!$I$4:$I$221,"Sim",Checklist!$J$4:$J$221,"A esclarecer") -> 0 | F16: =COUNTIFS(Checklist!$B$4:$B$221,$A16,Checklist!$I$4:$I$221,"Sim",Checklist!$J$4:$J$221,"N/A") -> 0 | G16: =B16-SUM(C16:F16) -> 11 | H16: =IF(B16=0,"-",(B16-G16)/B16) -> 0 | I16: =COUNTIFS(Checklist!$B$4:$B$221,$A16,Checklist!$I$4:$I$221,"Sim",Checklist!$J$4:$J$221,"Omisso",Checklist!$H$4:$H$221,"Alta") -> 0 | J16: =SUMIFS(Checklist!$N$4:$N$221,Checklist!$B$4:$B$221,$A16,Checklist!$I$4:$I$221,"Sim") -> 0
... A21: Licenças e Documentação | B21: =COUNTIFS(Checklist!$B$4:$B$221,$A21,Checklist!$I$4:$I$221,"Sim") -> 4 | C21: =COUNTIFS(Checklist!$B$4:$B$221,$A21,Checklist!$I$4:$I$221,"Sim",Checklist!$J$4:$J$221,"OK") -> 0 | D21: =COUNTIFS(Checklist!$B$4:$B$221,$A21,Checklist!$I$4:$I$221,"Sim",Checklist!$J$4:$J$221,"Omisso") -> 0 | E21: =COUNTIFS(Checklist!$B$4:$B$221,$A21,Checklist!$I$4:$I$221,"Sim",Checklist!$J$4:$J$221,"A esclarecer") -> 0 | F21: =COUNTIFS(Checklist!$B$4:$B$221,$A21,Checklist!$I$4:$I$221,"Sim",Checklist!$J$4:$J$221,"N/A") -> 0 | G21: =B21-SUM(C21:F21) -> 4 | H21: =IF(B21=0,"-",(B21-G21)/B21) -> 0 | I21: =COUNTIFS(Checklist!$B$4:$B$221,$A21,Checklist!$I$4:$I$221,"Sim",Checklist!$J$4:$J$221,"Omisso",Checklist!$H$4:$H$221,"Alta") -> 0 | J21: =SUMIFS(Checklist!$N$4:$N$221,Checklist!$B$4:$B$221,$A21,Checklist!$I$4:$I$221,"Sim") -> 0
A22: TOTAL | B22: =SUM(B5:B21) -> 188 | C22: =SUM(C5:C21) -> 0 | D22: =SUM(D5:D21) -> 0 | E22: =SUM(E5:E21) -> 0 | F22: =SUM(F5:F21) -> 0 | G22: =SUM(G5:G21) -> 188 | H22: =IF(B22=0,"-",(B22-G22)/B22) -> 0 | I22: =SUM(I5:I21) -> 0 | J22: =SUM(J5:J21) -> 0
A24: POR NATUREZA
A25: Natureza | B25: Pontos aplicáveis | C25: OK | D25: Omisso | E25: A esclarecer | F25: N/A | G25: Por verificar
A26: Omissão no MQ | B26: =COUNTIFS(Checklist!$G$4:$G$221,$A26,Checklist!$I$4:$I$221,"Sim") -> 120 | C26: =COUNTIFS(Checklist!$G$4:$G$221,$A26,Checklist!$I$4:$I$221,"Sim",Checklist!$J$4:$J$221,"OK") -> 0 | D26: =COUNTIFS(Checklist!$G$4:$G$221,$A26,Checklist!$I$4:$I$221,"Sim",Checklist!$J$4:$J$221,"Omisso") -> 0 | E26: =COUNTIFS(Checklist!$G$4:$G$221,$A26,Checklist!$I$4:$I$221,"Sim",Checklist!$J$4:$J$221,"A esclarecer") -> 0 | F26: =COUNTIFS(Checklist!$G$4:$G$221,$A26,Checklist!$I$4:$I$221,"Sim",Checklist!$J$4:$J$221,"N/A") -> 0 | G26: =B26-SUM(C26:F26) -> 120
A27: Omissão de projeto | B27: =COUNTIFS(Checklist!$G$4:$G$221,$A27,Checklist!$I$4:$I$221,"Sim") -> 11 | C27: =COUNTIFS(Checklist!$G$4:$G$221,$A27,Checklist!$I$4:$I$221,"Sim",Checklist!$J$4:$J$221,"OK") -> 0 | D27: =COUNTIFS(Checklist!$G$4:$G$221,$A27,Checklist!$I$4:$I$221,"Sim",Checklist!$J$4:$J$221,"Omisso") -> 0 | E27: =COUNTIFS(Checklist!$G$4:$G$221,$A27,Checklist!$I$4:$I$221,"Sim",Checklist!$J$4:$J$221,"A esclarecer") -> 0 | F27: =COUNTIFS(Checklist!$G$4:$G$221,$A27,Checklist!$I$4:$I$221,"Sim",Checklist!$J$4:$J$221,"N/A") -> 0 | G27: =B27-SUM(C27:F27) -> 11
A28: Compatibilização | B28: =COUNTIFS(Checklist!$G$4:$G$221,$A28,Checklist!$I$4:$I$221,"Sim") -> 57 | C28: =COUNTIFS(Checklist!$G$4:$G$221,$A28,Checklist!$I$4:$I$221,"Sim",Checklist!$J$4:$J$221,"OK") -> 0 | D28: =COUNTIFS(Checklist!$G$4:$G$221,$A28,Checklist!$I$4:$I$221,"Sim",Checklist!$J$4:$J$221,"Omisso") -> 0 | E28: =COUNTIFS(Checklist!$G$4:$G$221,$A28,Checklist!$I$4:$I$221,"Sim",Checklist!$J$4:$J$221,"A esclarecer") -> 0 | F28: =COUNTIFS(Checklist!$G$4:$G$221,$A28,Checklist!$I$4:$I$221,"Sim",Checklist!$J$4:$J$221,"N/A") -> 0 | G28: =B28-SUM(C28:F28) -> 57
A30: Fórmulas: contagens com COUNTIFS sobre a folha Checklist, considerando apenas pontos com «Aplicável nesta obra» = Sim. «Por verificar» = aplicáveis − (OK + Omisso + A esclarecer + N/A).

Sheet Checklist
A1: CHECKLIST DE OMISSÕES E COMPATIBILIZAÇÃO
A2: ="Obra: "&IF(Instruções!$C$4="","(preencher em Instruções)",Instruções!$C$4)&" · Tipo: "&IF(Instruções!$C$5="","(todos os pontos)",Instruções!$C$5) -> Obra: (preencher em Instruções) · Tipo: (todos os pontos)
A3: ID | B3: Especialidade | C3: Grupo | D3: Ponto de verificação | E3: Aplica-se a | F3: Onde verificar | G3: Natureza | H3: Gravidade típica | I3: Aplicável nesta obra | J3: Estado | K3: Capítulo / Artigo do MQ | L3: Desenho / Peça de referência | M3: Observações / Ação proposta | N3: Valor estimado (€)
A4: GER-01 | B4: Gerais e Estaleiro | C4: Estaleiro | D4: Montagem, manutenção e desmontagem do estaleiro (instalações, vedação, sinalização) | E4: Ambas | F4: MQ | G4: Omissão no MQ | H4: Alta | I4: =IF(OR(E4="Ambas",Instruções!$C$5="",E4=Instruções!$C$5),"Sim","Não") -> Sim
A5: GER-02 | B5: Gerais e Estaleiro | C5: Estaleiro | D5: Ligações provisórias de água, eletricidade e esgoto de obra e respetivos consumos | E5: Ambas | F5: MQ | G5: Omissão no MQ | H5: Média | I5: =IF(OR(E5="Ambas",Instruções!$C$5="",E5=Instruções!$C$5),"Sim","Não") -> Sim
A6: GER-03 | B6: Gerais e Estaleiro | C6: Estaleiro | D6: Andaimes e plataformas de trabalho para fachadas e cobertura | E6: Ambas | F6: MQ | G6: Omissão no MQ | H6: Alta | I6: =IF(OR(E6="Ambas",Instruções!$C$5="",E6=Instruções!$C$5),"Sim","Não") -> Sim
A7: GER-04 | B7: Gerais e Estaleiro | C7: Estaleiro | D7: Meios de elevação (grua/monta-cargas) e licença de ocupação da via pública | E7: Ambas | F7: MQ | G7: Omissão no MQ | H7: Média | I7: =IF(OR(E7="Ambas",Instruções!$C$5="",E7=Instruções!$C$5),"Sim","Não") -> Sim
A8: GER-05 | B8: Gerais e Estaleiro | C8: Estaleiro | D8: Implantação topográfica e piquetagem da obra | E8: Construção nova | F8: MQ | G8: Omissão no MQ | H8: Média | I8: =IF(OR(E8="Ambas",Instruções!$C$5="",E8=Instruções!$C$5),"Sim","Não") -> Sim
A9: GER-06 | B9: Gerais e Estaleiro | C9: Segurança e ambiente | D9: Implementação do Plano de Segurança e Saúde (EPC, sinalização, proteções coletivas) | E9: Ambas | F9: MQ / CTE | G9: Omissão no MQ | H9: Média | I9: =IF(OR(E9="Ambas",Instruções!$C$5="",E9=Instruções!$C$5),"Sim","Não") -> Sim
A10: GER-07 | B10: Gerais e Estaleiro | C10: Segurança e ambiente | D10: Plano de Prevenção e Gestão de RCD, triagem, transporte e deposição em operador licenciado | E10: Ambas | F10: MQ | G10: Omissão no MQ | H10: Alta | I10: =IF(OR(E10="Ambas",Instruções!$C$5="",E10=Instruções!$C$5),"Sim","Não") -> Sim
A11: GER-08 | B11: Gerais e Estaleiro | C11: Segurança e ambiente | D11: Proteção de construções vizinhas, vistoria prévia e registo fotográfico | E11: Ambas | F11: MQ / MD | G11: Omissão no MQ | H11: Média | I11: =IF(OR(E11="Ambas",Instruções!$C$5="",E11=Instruções!$C$5),"Sim","Não") -> Sim
A12: GER-09 | B12: Gerais e Estaleiro | C12: Finalização | D12: Limpezas periódicas e limpeza final da obra | E12: Ambas | F12: MQ | G12: Omissão no MQ | H12: Baixa | I12: =IF(OR(E12="Ambas",Instruções!$C$5="",E12=Instruções!$C$5),"Sim","Não") -> Sim
A13: GER-10 | B13: Gerais e Estaleiro | C13: Finalização | D13: Telas finais, compilação técnica e manuais de utilização e manutenção | E13: Ambas | F13: MQ / CTE | G13: Omissão no MQ | H13: Média | I13: =IF(OR(E13="Ambas",Instruções!$C$5="",E13=Instruções!$C$5),"Sim","Não") -> Sim
A14: GER-11 | B14: Gerais e Estaleiro | C14: Coerência documental | D14: Descrições e unidades do MQ coerentes com a memória descritiva e o caderno de encargos | E14: Ambas | F14: MQ / CTE / MD | G14: Compatibilização | H14: Alta | I14: =IF(OR(E14="Ambas",Instruções!$C$5="",E14=Instruções!$C$5),"Sim","Não") -> Sim
A15: GER-12 | B15: Gerais e Estaleiro | C15: Coerência documental | D15: Todas as especialidades desenvolvidas sobre a mesma revisão de arquitetura | E15: Ambas | F15: Legendas dos desenhos | G15: Compatibilização | H15: Alta | I15: =IF(OR(E15="Ambas",Instruções!$C$5="",E15=Instruções!$C$5),"Sim","Não") -> Sim
... A191: LIC-04 | B191: Licenças e Documentação | C191: Documentação | D191: Inspeções e vistorias finais para autorização de utilização | E191: Ambas | F191: MQ | G191: Omissão no MQ | H191: Baixa | I191: =IF(OR(E191="Ambas",Instruções!$C$5="",E191=Instruções!$C$5),"Sim","Não") -> Sim
I192: =IF(D192="","",IF(OR(E192="Ambas",E192="",Instruções!$C$5="",E192=Instruções!$C$5),"Sim","Não"))
I193: =IF(D193="","",IF(OR(E193="Ambas",E193="",Instruções!$C$5="",E193=Instruções!$C$5),"Sim","Não"))
I194: =IF(D194="","",IF(OR(E194="Ambas",E194="",Instruções!$C$5="",E194=Instruções!$C$5),"Sim","Não"))
I195: =IF(D195="","",IF(OR(E195="Ambas",E195="",Instruções!$C$5="",E195=Instruções!$C$5),"Sim","Não"))
I196: =IF(D196="","",IF(OR(E196="Ambas",E196="",Instruções!$C$5="",E196=Instruções!$C$5),"Sim","Não"))
I197: =IF(D197="","",IF(OR(E197="Ambas",E197="",Instruções!$C$5="",E197=Instruções!$C$5),"Sim","Não"))
I198: =IF(D198="","",IF(OR(E198="Ambas",E198="",Instruções!$C$5="",E198=Instruções!$C$5),"Sim","Não"))
I199: =IF(D199="","",IF(OR(E199="Ambas",E199="",Instruções!$C$5="",E199=Instruções!$C$5),"Sim","Não"))
I200: =IF(D200="","",IF(OR(E200="Ambas",E200="",Instruções!$C$5="",E200=Instruções!$C$5),"Sim","Não"))
I201: =IF(D201="","",IF(OR(E201="Ambas",E201="",Instruções!$C$5="",E201=Instruções!$C$5),"Sim","Não"))
I202: =IF(D202="","",IF(OR(E202="Ambas",E202="",Instruções!$C$5="",E202=Instruções!$C$5),"Sim","Não"))
I203: =IF(D203="","",IF(OR(E203="Ambas",E203="",Instruções!$C$5="",E203=Instruções!$C$5),"Sim","Não"))
... I221: =IF(D221="","",IF(OR(E221="Ambas",E221="",Instruções!$C$5="",E221=Instruções!$C$5),"Sim","Não"))
