Workbook

Sheet Leia-me
B1: Medição preliminar – Moradia bifamiliar Apúlia (Vendeiro)
B2: v1 · Elaborada a partir das peças escritas dos projetos (sem MQ do projetista) · Para validação
B4: Confiança A | C4: Medição do projeto
B5: Confiança B | C5: Calculado a partir de dados do projeto
B6: Confiança C | C6: Estimativa por rácio / pressuposto
B7: Confiança D | C7: Verba a medir / a confirmar
C9: • Rastreabilidade: cada quantidade do MQ remete para uma linha da folha «Cálculos» (fórmula + fonte). Altere os dados de base (D01–D20) e tudo recalcula.
C10: • Arquitetura: os desenhos do PDF usam fontes não extraíveis; as áreas dos compartimentos foram lidas nas plantas incluídas nos projetos de Gás/Residuais.
C11: • Estrutura: volumes de pilares e vigas estimados (secções reais, comprimentos/alturas aproximados). Aço por rácio. Validar com medição sobre desenhos.
C12: • Elétrico: desenhos não legíveis → pontos de luz/tomadas por rácio (0,25 e 0,35 por m² útil).
C13: • Omissões identificadas e já incluídas: válvula antirretorno (cadastro EAmb), ATE do ITED (qtd 0 no projeto), hidrante SCIE, poço de infiltração pluvial.
C14: • Fora de medição (confiança D): demolição do existente, arranjos exteriores, guardas, pintura exterior, luminárias, cozinhas.
B16: Resumo da confiança
B17: A – Medição do projeto | C17: 51 artigos
B18: B – Calculado a partir de dados do projeto | C18: 26 artigos
B19: C – Estimativa por rácio / pressuposto | C19: 35 artigos
B20: D – Verba a medir / a confirmar | C20: 6 artigos

Sheet MQ_Preliminar
A1: MAPA DE QUANTIDADES PRELIMINAR
A2: Obra: Moradia bifamiliar – Rua da Ponte Nova 30, Apúlia (Esposende) · Requerente: M. A. S. R. Vendeiro
A4: Artº | B4: Descrição | C4: Un | D4: Quant. | E4: Origem / cálculo | F4: Confiança
A5: 1 | B5: ESTALEIRO, TRABALHOS PREPARATÓRIOS E DEMOLIÇÕES
A6: 1.1 | B6: Montagem, manutenção e desmontagem de estaleiro, incluindo vedação, sinalização, instalações e ligações provisórias | C6: vg | D6: =1 -> 1 | E6: Checklist GER-01/02 | F6: C
A7: 1.2 | B7: Demolição do edifício existente, incluindo triagem, transporte e deposição de RCD em operador licenciado | C7: vg | D7: =1 -> 1 | E7: Projeto: 'demolição de edifício' – área existente não consta; medir em visita | F7: D
A8: 1.3 | B8: Plano de prevenção e gestão de RCD e implementação do PSS | C8: vg | D8: =1 -> 1 | E8: Checklist GER-06/07 | F8: C
A9: 1.4 | B9: Implantação topográfica e piquetagem | C9: vg | D9: =1 -> 1 | E9: Checklist GER-05 | F9: C
A10: 2 | B10: MOVIMENTO DE TERRAS
A11: 2.1 | B11: Escavação em terreno médio para abertura de caboucos de sapatas e vigas de fundação | C11: m³ | D11: =Cálculos!$E$39 -> 30.7905 | E11: Calc. E16 | F11: B
A12: 2.2 | B12: Aterro e compactação com material selecionado | C12: m³ | D12: =ROUND(Cálculos!$E$39*0.35,1) -> 10.8 | E12: ≈35% do escavado | F12: C
A13: 2.3 | B13: Transporte de terras sobrantes a vazadouro | C13: m³ | D13: =ROUND(Cálculos!$E$39*0.65*1.25,1) -> 25 | E13: ≈65% do escavado × empolamento 1,25 | F13: C
A14: 2.4 | B14: Caixa de brita 30/50 compactada, e=0,15 m, com geotêxtil e duplo filme de polietileno sob pavimento térreo | C14: m³ | D14: =Cálculos!$E$40 -> 13.6605 | E14: Calc. E17 / Estab. pormenor PT1 | F14: B
A15: 3 | B15: ESTRUTURA DE BETÃO ARMADO
A16: 3.1 | B16: Betão de limpeza C16/20 | C16: m³ | D16: =Cálculos!$E$33 -> 5.92125 | E16: Calc. E10 | F16: B
A17: 3.2 | B17: Betão em fundações C25/30 (exec. c/ bomba) – sapatas e lintéis de fundação | C17: m³ | D17: =Cálculos!$E$24+Cálculos!$E$25+Cálculos!$E$26 -> 23.685 | E17: Calc. E01+E02+E03 | F17: B
A18: 3.3 | B18: Betão em pilares C25/30 | C18: m³ | D18: =Cálculos!$E$27 -> 14.08 | E18: Calc. E04 | F18: C
A19: 3.4 | B19: Betão em vigas C25/30 | C19: m³ | D19: =Cálculos!$E$28 -> 18 | E19: Calc. E05 | F19: C
A20: 3.5 | B20: Laje aligeirada de vigotas pré-esforçadas 20+5 (INORBEL ou equivalente), C25/30 | C20: m² | D20: =Cálculos!$E$29 -> 258.3 | E20: Calc. E06 | F20: B
A21: 3.6 | B21: Betão em laje maciça C25/30 | C21: m³ | D21: =Cálculos!$E$30 -> 3.75 | E21: Calc. E07 | F21: C
A22: 3.7 | B22: Betão em escadas C25/30 | C22: m³ | D22: =Cálculos!$E$31 -> 3 | E22: Calc. E08 | F22: C
A23: 3.8 | B23: Pavimento térreo em betão armado com malhasol AQ50 e hidrófugo | C23: m² | D23: =Cálculos!$E$32 -> 91.07 | E23: Calc. E09 / Estab. PT1 | F23: B
A24: 3.9 | B24: Aço A400 em varão (fornecimento e colocação) | C24: kg | D24: =ROUND(Cálculos!$E$34+Cálculos!$E$35+Cálculos!$E$36,0) -> 6199 | E24: Calc. E11–E13 (rácios) | F24: C
A25: 3.10 | B25: Cofragem recuperável em pilares | C25: m² | D25: =Cálculos!$E$37 -> 183.04 | E25: Calc. E14 | F25: C
A26: 3.11 | B26: Cofragem recuperável em vigas | C26: m² | D26: =Cálculos!$E$38 -> 189 | E26: Calc. E15 | F26: C
A27: 3.12 | B27: Impermeabilização de elementos enterrados com duas demãos de pintura asfáltica | C27: m² | D27: =ROUND((Cálculos!$E$24+Cálculos!$E$25+Cálculos!$E$26)*2.5,1) -> 59.2 | E27: Estab. – nota elementos enterrados (≈2,5 m²/m³) | F27: C
A28: 4 | B28: ALVENARIAS E DIVISÓRIAS
A29: 4.1 | B29: Parede exterior em alvenaria de bloco térmico 25 cm | C29: m² | D29: =Cálculos!$E$41 -> 160.15 | E29: Calc. A01 | F29: B
A30: 4.2 | B30: Paredes interiores em tijolo 11 | C30: m² | D30: =Cálculos!$E$42 -> 182.7 | E30: Calc. A02 (rácio) | F30: C
A31: 4.3 | B31: Forro interior em dupla placa de gesso cartonado com caixa de ar e lã mineral | C31: m² | D31: =Cálculos!$E$43 -> 166.3 | E31: Calc. A03 | F31: B
A32: 4.4 | B32: Lintéis, vergas e remates de vãos em alvenaria | C32: m | D32: =Cálculos!$E$18 -> 79.95 | E32: Térmico – contorno de caixilharia | F32: C
A33: 5 | B33: REVESTIMENTOS E ISOLAMENTOS
A34: 5.1 | B34: ETICS parede exterior (isolamento 80 mm + acabamento), incluindo perfis e reforços de vãos | C34: m² | D34: =Cálculos!$E$44 -> 93.19 | E34: Calc. A04 – confirmar EPS/XPS (divergência Acústica) | F34: B
A35: 5.2 | B35: Reboco interior e estuque projetado em paredes | C35: m² | D35: =Cálculos!$E$47 -> 451.35068 | E35: Calc. A07 | F35: C
A36: 5.3 | B36: Pintura interior tinta plástica (2 demãos c/ primário) em paredes e tetos | C36: m² | D36: =Cálculos!$E$47+Cálculos!$E$52+Cálculos!$E$53 -> 632.66068 | E36: Calc. A07+A12+A13 | F36: C
A37: 5.4 | B37: Revestimento cerâmico parede interior (I.S. e cozinhas) | C37: m² | D37: =Cálculos!$E$45+Cálculos!$E$46 -> 80.349319 | E37: Calc. A05+A06 | F37: B
A38: 5.5 | B38: Betonilha de regularização de pavimentos | C38: m² | D38: =Cálculos!$E$49 -> 181.31 | E38: Calc. A09 | F38: B
A39: 5.6 | B39: Lajeta flutuante 8 cm com manta acústica de impacto (pavimento Fração B) | C39: m² | D39: =Cálculos!$E$50 -> 81.07 | E39: Acústica PAVE1 | F39: B
A40: 5.7 | B40: Pavimento cerâmico (colocação e fornecimento) | C40: m² | D40: =Cálculos!$E$48 -> 181.31 | E40: Plantas | F40: A
A41: 5.8 | B41: Rodapé | C41: m | D41: =ROUND(Cálculos!$E$51,0) -> 140 | E41: Calc. A11 | F41: C
...

Sheet Cálculos
A1: CÁLCULOS AUXILIARES (fórmulas rastreáveis)
A3: ID | B3: Descrição | C3: Expressão | E3: Resultado | F3: Un | G3: Fonte | H3: Conf.
A4: D01 | B4: Área útil Fração A (T2, RC) | C4: 77.5 | E4: =77.5 -> 77.5 | F4: m² | G4: Térmico – Ficha 1 Fração A | H4: A
A5: D02 | B5: Área útil Fração B (T3, andar) | C5: 125.5 | E5: =125.5 -> 125.5 | F5: m² | G5: Térmico – Ficha 1 Fração B | H5: A
A6: D03 | B6: Área bruta de construção | C6: 390.6 | E6: =390.6 -> 390.6 | F6: m² | G6: Arquitetura – estimativa custo / SCIE ficha | H6: A
A7: D04 | B7: Paredes exteriores PDE1 Fração A (opaco) | C7: 12.70+3.60+13.45 | E7: =12.7+3.6+13.45 -> 29.75 | F7: m² | G7: Térmico – Folha cálculo A (A.1) | H7: A
A8: D05 | B8: Paredes exteriores PDE1 Fração B (opaco) | C8: 20.45+10.30+10.55 | E8: =20.45+10.3+10.55 -> 41.3 | F8: m² | G8: Térmico – Folha cálculo B (A.1) | H8: A
A9: D06 | B9: Pontes térmicas planas PTPPDE1 (A+B) | C9: 0.90+0.90+1.75+2.60 | E9: =0.9+0.9+1.75+2.6 -> 6.15 | F9: m² | G9: Térmico – Folhas A e B | H9: A
A10: D07 | B10: Envidraçados Fração A | C10: 31.32/1.80 | E10: =31.32/1.8 -> 17.4 | F10: m² | G10: Térmico – ΣU.A / U (1,80) | H10: B
A11: D08 | B11: Envidraçados Fração B | C11: 50.94/1.80 | E11: =50.94/1.8 -> 28.3 | F11: m² | G11: Térmico – ΣU.A / U (1,80) | H11: B
A12: D09 | B12: Paredes em contacto com edifício adjacente PDI2 (A+B) | C12: 27.75+44.15 | E12: =27.75+44.15 -> 71.9 | F12: m² | G12: Térmico – Folhas A e B (A.2) | H12: A
A13: D10 | B13: Paredes em contacto com área técnica PDI1 (A+B) | C13: 10.15+7.05 | E13: =10.15+7.05 -> 17.2 | F13: m² | G13: Térmico – Folhas A e B (A.2) | H13: A
A14: D11 | B14: Cobertura exterior CBE1 (A) | C14: 19.05 | E14: =19.05 -> 19.05 | F14: m² | G14: Térmico – Folha A | H14: A
A15: D12 | B15: Laje sob desvão de cobertura CBI1 (B) | C15: 113.75 | E15: =113.75 -> 113.75 | F15: m² | G15: Térmico – Folha B | H15: A
A16: D13 | B16: Pavimento sobre exterior PVE1 (B) | C16: 36.95 | E16: =36.95 -> 36.95 | F16: m² | G16: Térmico – Folha B | H16: A
A17: D14 | B17: Pavimento sobre desvão sanitário PVI1 (A) + PVI1/PVI2 (B) | C17: 77.55+10.80+3.45 | E17: =77.55+10.8+3.45 -> 91.8 | F17: m² | G17: Térmico – Folhas A e B | H17: A
A18: D15 | B18: Comprimento de contorno de caixilharia (A+B) | C18: 29.00+50.95 | E18: =29+50.95 -> 79.95 | F18: m | G18: Térmico – pontes térmicas lineares | H18: A
A19: D16 | B19: Comprimento de caixas de estore (A+B) | C19: 7.05+13.80 | E19: =7.05+13.8 -> 20.85 | F19: m | G19: Térmico – pontes térmicas lineares | H19: A
A20: D17 | B20: Área de cobertura drenada (projeção) | C20: 70.66+75.73 | E20: =70.66+75.73 -> 146.39 | F20: m² | G20: Pluviais – tubos de queda P1+P2 | H20: A
A21: D18 | B21: Terraços / varandas drenados (piso 2) | C21: 50.77+44.12+2.85 | E21: =50.77+44.12+2.85 -> 97.74 | F21: m² | G21: Pluviais – ramais A1+A2+A3 | H21: A
A22: D19 | B22: Áreas compartimentos RC (Fração A) | C22: 1.33+2.50+3.48+4.16+10.69+10.92+37.81+10.18 | E22: =1.33+2.5+3.48+4.16+10.69+10.92+37.81+10.18 -> 81.07 | F22: m² | G22: Plantas (legendas nos PDF Gás/Residuais) | H22: A
A23: D20 | B23: Áreas compartimentos andar (Fração B) | C23: 4.00+18.86+13.94+4.69+30.35+11.97+4.25+12.18 | E23: =4+18.86+13.94+4.69+30.35+11.97+4.25+12.18 -> 100.24 | F23: m² | G23: Plantas (legendas nos PDF Gás/Residuais) | H23: A
A24: E01 | B24: Volume sapatas do quadro (P4,P7,P9,P12,P13,P14,P15,P22,P16,P18,P17,P19,P20,P21,P5-6,P11-24) | C24: 3*1.35*1.35*0.4+1.85*0.95*0.4+2.6*1.3*0.6+2.1*1*0.4+2*1.4*0.8*0.4+2*1.35*1.35*0.4+1.65*1.65*0.4+2*0.8*1.4*0.4+0.9*0.9*0.4+2.3*0.9*0.4+3.4*1.35*0.4 | E24: =3*1.35*1.35*0.4+1.85*0.95*0.4+2.6*1.3*0.6+2.1*1*0.4+2*1.4*0.8*0.4+2*1.35*1.35*0.4+1.65*1.65*0.4+2*0.8*1.4*0.4+0.9*0.9*0.4+2.3*0.9*0.4+3.4*1.35*0.4 -> 13.085 | F24: m³ | G24: Estabilidade – Quadro de sapatas (des. 01) | H24: B
A25: E02 | B25: Sapatas P1,P2,P3,P8 (não constam do quadro – assumido 1,00×1,00×0,40) | C25: 4*1*1*0.4 | E25: =4*1*1*0.4 -> 1.6 | F25: m³ | G25: Pressuposto – pedir esclarecimento | H25: C
A26: E03 | B26: Vigas de fundação VF1 (≈75 m × 0,30 × 0,40 – secção não legível) | C26: 75*0.30*0.40 | E26: =75*0.3*0.4 -> 9 | F26: m³ | G26: Estimativa – perímetro implantação ≈50 m + alinhamentos interiores ≈25 m | H26: C
A27: E04 | B27: Pilares (22 un × secção média 0,25×0,40 × altura média 6,4 m) | C27: 22*0.25*0.40*6.4 | E27: =22*0.25*0.4*6.4 -> 14.08 | F27: m³ | G27: Estabilidade – quadro pilares (22 un); altura 2×3,20 m | H27: C
A28: E05 | B28: Vigas (≈180 m × secção média 0,25×0,40) | C28: 180*0.25*0.40 | E28: =180*0.25*0.4 -> 18 | F28: m³ | G28: Estabilidade – pórticos piso 1, piso 2, cobertura (estimativa de comprimentos) | H28: C
A29: E06 | B29: Lajes aligeiradas 20+5 (piso 2 + cobertura) | C29: D02+D12+D11 | E29: =Cálculos!$E$5+Cálculos!$E$15+Cálculos!$E$14 -> 258.3 | F29: m² | G29: Térmico: área piso B (125,5) + CBI1 + CBE1 | H29: B
A30: E07 | B30: Lajes maciças LM1 h=0,25 (varandas/patamares ≈15 m²) | C30: 15*0.25 | E30: =15*0.25 -> 3.75 | F30: m³ | G30: Estimativa – plantas estruturais | H30: C
A31: E08 | B31: Escada interior em betão armado | C31: 3 | E31: =3 -> 3 | F31: m³ | G31: Estimativa – 1 escada (2 lanços + patamar) | H31: C
A32: E09 | B32: Pavimento térreo PT1 (laje térrea sobre brita) – implantação RC | C32: D19+10 | E32: =Cálculos!$E$22+10 -> 91.07 | F32: m² | G32: Áreas RC + paredes (≈10 m²) | H32: B
A33: E10 | B33: Betão de limpeza (sapatas + VF, e=0,10) | C33: (E01+E02)/0.4*0.10+75*0.30*0.10 | E33: =(Cálculos!$E$24+Cálculos!$E$25)/0.4*0.1+75*0.3*0.1 -> 5.92125 | F33: m³ | G33: Calculado de E01–E03 | H33: B
A34: E11 | B34: Aço A400 – fundações (≈60 kg/m³) | C34: (E01+E02+E03)*60 | E34: =(Cálculos!$E$24+Cálculos!$E$25+Cálculos!$E$26)*60 -> 1421.1 | F34: kg | G34: Rácio corrente | H34: C
A35: E12 | B35: Aço A400 – pilares e vigas (≈130 kg/m³) | C35: (E04+E05)*130 | E35: =(Cálculos!$E$27+Cálculos!$E$28)*130 -> 4170.4 | F35: kg | G35: Rácio corrente | H35: C
A36: E13 | B36: Aço A400 – lajes maciças e escada (≈90 kg/m³) | C36: (E07+E08)*90 | E36: =(Cálculos!$E$30+Cálculos!$E$31)*90 -> 607.5 | F36: kg | G36: Rácio corrente | H36: C
A37: E14 | B37: Cofragem pilares (perímetro médio 1,30 m × 6,4 m × 22) | C37: 22*1.30*6.4 | E37: =22*1.3*6.4 -> 183.04 | F37: m² | G37: Calculado de E04 | H37: C
A38: E15 | B38: Cofragem vigas ((2×0,40+0,25) × 180 m) | C38: (2*0.40+0.25)*180 | E38: =(2*0.4+0.25)*180 -> 189 | F38: m² | G38: Calculado de E05 | H38: C
A39: E16 | B39: Escavação caboucos (sapatas+VF ×1,3) | C39: (E01+E02+E03)*1.3 | E39: =(Cálculos!$E$24+Cálculos!$E$25+Cálculos!$E$26)*1.3 -> 30.7905 | F39: m³ | G39: Calculado | H39: B
A40: E17 | B40: Caixa de brita 30/50 e=0,15 sob PT1 | C40: E09*0.15 | E40: =Cálculos!$E$32*0.15 -> 13.6605 | F40: m³ | G40: Estabilidade – pormenor PT1 | H40: B
A41: A01 | B41: Alvenaria exterior bloco térmico 25 cm (PDE1 + PDI1 + PDI2) | C41: D04+D05+D10+D09 | E41: =Cálculos!$E$7+Cálculos!$E$8+Cálculos!$E$13+Cálculos!$E$12 -> 160.15 | F41: m² | G41: Térmico (áreas opacas) | H41: B
...
